Workbook

Sheet GIA CONG ACRYLIC
L3: TRẢ LÕI CNC
G5: BÁO GIÁ KIÊM ĐƠN ĐẶT HÀNG
G6: Ngày 23 tháng 6 năm 2026 | L6: Ngày giờ chốt đơn: | M6: 46196.643
G7: Số phiếu: | H7: L3287 | L7: Số ngày phải giao từ lúc chốt đơn: | M7: 2
C8: Khách hàng: KH0457D - Anh Giang Kle (Chinh) | L8: Ngày giờ phải giao hàng: | M8: =M6+M7 -> 46198.643
C9: Địa chỉ: TT Đô Lương 0929903777 - 0989998060
C10: Công ty TNHH Gỗ GERVIN xin cảm ơn quý khách hàng đã tin dùng sản phẩm của chúng tôi và xin được báo giá như sau:
A11: Stt | B11: Mã hàng | C11: Tên hàng hóa, dịch vụ | D11: Kích thước (mm) | F11: Số lượng | G11: Cạnh vát | H11: Chiều vân | I11: Cánh (m2) | J11: Thanh phào (m) | K11: Đơn giá | L11: Thành tiền | M11: GHI CHÚ | N11: Kính đố 70 hèm s5r10 | O11: CNC như hình vẽ
D12: Cao (chiều vân gỗ) | E12: Rộng | N12: Vát | O12: Vân dọc
A13: I | C13: Acrylic màu 1 | F13: =SUM(F14:F32) -> 19 | I13: =SUM(I14:I32) -> 3.437301 | J13: =SUM(J14:J32) -> 2.663
A14: 1 | B14: GV26**.TP | C14: Cốt MDF, 1 mặt Acrylic GV26 nhũ chống xước cao, 1 mặt acrylic chống cong vênh trắng bóng | D14: 732 | E14: 435 | F14: 1 | G14: =$N$12&N14 -> Vát 435 | I14: =D14*E14*F14/1000000 -> 0.31842 | K14: 1350000 | L14: =ROUND((I14+J14)*K14,0) -> 429867 | M14: tủ dưới phải Cánh Phải- | N14: =E14 -> 435 | O14: vát cạnh ngắn
A15: 2 | B15: GV26**.TP | D15: 732 | E15: 435 | F15: 1 | G15: =$N$12&N15 -> Vát 435 | I15: =D15*E15*F15/1000000 -> 0.31842 | K15: 1350000 | L15: =ROUND((I15+J15)*K15,0) -> 429867 | M15: tủ dưới phải Cánh Trái- | N15: =E15 -> 435 | O15: vát cạnh ngắn
A16: 3 | B16: GV26**.TP | D16: 2182 | E16: 80 | F16: 1 | I16: =D16*E16*F16/1000000 -> 0.17456 | K16: 1350000 | L16: =ROUND((I16+J16)*K16,0) -> 235656 | M16: tủ dưới phải xà trên
A17: 4 | B17: GV26**.TP | D17: 800 | E17: 50 | F17: 1 | J17: =D17/1000*F17 -> 0.8 | K17: 100000 | L17: =ROUND((I17+J17)*K17,0) -> 80000 | M17: tủ dưới trái Xà
A18: 5 | B18: GV26**.TP | D18: 1597 | E18: 80 | F18: 1 | I18: =D18*E18*F18/1000000 -> 0.12776 | K18: 1350000 | L18: =ROUND((I18+J18)*K18,0) -> 172476 | M18: tủ dưới trái xà trên
A19: 6 | B19: GV26**.TP | D19: 303 | E19: 546 | F19: 1 | G19: =$N$12&N19 -> Vát 546 | I19: =D19*E19*F19/1000000 -> 0.165438 | K19: 1350000 | L19: =ROUND((I19+J19)*K19,0) -> 223341 | M19: tủ đồ khô Mặt Hộc | N19: =E19 -> 546 | O19: vát cạnh dài
A20: 7 | B20: GV26**.TP | D20: 296 | E20: 546 | F20: 1 | G20: =$N$12&N20 -> Vát 546 | I20: =D20*E20*F20/1000000 -> 0.161616 | K20: 1350000 | L20: =ROUND((I20+J20)*K20,0) -> 218182 | M20: tủ đồ khô Mặt Hộc | N20: =E20 -> 546 | O20: vát cạnh dài
A21: 8 | B21: GV26**.TP | D21: 564 | E21: 50 | F21: 1 | J21: =D21/1000*F21 -> 0.564 | K21: 100000 | L21: =ROUND((I21+J21)*K21,0) -> 56400 | M21: tủ đồ khô Xà
A22: 9 | B22: GV26**.TP | D22: 564 | E22: 50 | F22: 1 | J22: =D22/1000*F22 -> 0.564 | K22: 100000 | L22: =ROUND((I22+J22)*K22,0) -> 56400 | M22: tủ đồ khô Xà
A23: 10 | B23: GV26**.TP | D23: 834 | E23: 70 | F23: 1 | I23: =D23*E23*F23/1000000 -> 0.05838 | K23: 1350000 | L23: =ROUND((I23+J23)*K23,0) -> 78813 | M23: tủ dưới phải dưới Xà
A24: 11 | B24: GV26**.TP | D24: 733 | E24: 315 | F24: 1 | G24: =$N$12&N24 -> Vát 315 | I24: =D24*E24*F24/1000000 -> 0.230895 | K24: 1350000 | L24: =ROUND((I24+J24)*K24,0) -> 311708 | M24: tủ dưới phải Mặt Hộc | N24: =E24 -> 315 | O24: vát cạnh ngắn
A25: 12 | B25: GV26**.TP | D25: 1492 | E25: 100 | F25: 1 | I25: =D25*E25*F25/1000000 -> 0.1492 | K25: 1350000 | L25: =ROUND((I25+J25)*K25,0) -> 201420 | M25: tủ dưới phải xà chân trước
A26: 13 | B26: GV26**.TP | D26: 835 | E26: 600 | F26: 1 | I26: =D26*E26*F26/1000000 -> 0.501 | K26: 1350000 | L26: =ROUND((I26+J26)*K26,0) -> 676350 | M26: tủ dưới trái
A27: 14 | B27: GV26**.TP | D27: 354 | E27: 781 | F27: 1 | G27: =$N$12&N27 -> Vát 781 | I27: =D27*E27*F27/1000000 -> 0.276474 | K27: 1350000 | L27: =ROUND((I27+J27)*K27,0) -> 373240 | M27: tủ dưới trái Cánh Phải- | N27: =E27 -> 781 | O27: vát cạnh dài
A28: 15 | B28: GV26**.TP | D28: 354 | E28: 781 | F28: 1 | G28: =$N$12&N28 -> Vát 781 | I28: =D28*E28*F28/1000000 -> 0.276474 | K28: 1350000 | L28: =ROUND((I28+J28)*K28,0) -> 373240 | M28: tủ dưới trái Cánh Trái- | N28: =E28 -> 781 | O28: vát cạnh dài
A29: 16 | B29: GV26**.TP | D29: 733 | E29: 377 | F29: 1 | G29: =$N$12&N29 -> Vát 377 | I29: =D29*E29*F29/1000000 -> 0.276341 | K29: 1350000 | L29: =ROUND((I29+J29)*K29,0) -> 373060 | M29: tủ dưới trái Cánh phải- | N29: =E29 -> 377 | O29: vát cạnh ngắn
A30: 17 | B30: GV26**.TP | D30: 733 | E30: 331 | F30: 1 | G30: =$N$12&N30 -> Vát 331 | I30: =D30*E30*F30/1000000 -> 0.242623 | K30: 1350000 | L30: =ROUND((I30+J30)*K30,0) -> 327541 | M30: tủ dưới trái Mặt Hộc | N30: =E30 -> 331 | O30: vát cạnh ngắn
A31: 18 | B31: GV26**.TP | D31: 735 | E31: 50 | F31: 1 | J31: =D31/1000*F31 -> 0.735 | K31: 100000 | L31: =ROUND((I31+J31)*K31,0) -> 73500 | M31: tủ dưới trái tủ bếp dưới Xà
A32: 19 | B32: GV26**.TP | D32: 1597 | E32: 100 | F32: 1 | I32: =D32*E32*F32/1000000 -> 0.1597 | K32: 1350000 | L32: =ROUND((I32+J32)*K32,0) -> 215595 | M32: tủ dưới trái xà chân trước
A33: II | C33: Acrylic màu 2 | F33: =SUM(F34:F64) -> 31 | I33: =SUM(I34:I64) -> 9.193913 | J33: =SUM(J34:J64) -> 1.505
A34: 1 | B34: GV21.TP | C34: Cốt MDF, 1 mặt Acrylic GV21, 1 mặt acrylic chống cong vênh trắng bóng | D34: 800 | E34: 50 | F34: 1 | J34: =D34/1000*F34 -> 0.8 | K34: 100000 | L34: =ROUND((I34+J34)*K34,0) -> 80000 | M34: tủ dưới trái Hồi-
A35: 2 | B35: GV21.TP | D35: 703 | E35: 455 | F35: 1 | I35: =D35*E35*F35/1000000 -> 0.319865 | K35: 1120000 | L35: =ROUND((I35+J35)*K35,0) -> 358249 | M35: tủ kịch trần phải Cánh phải-
A36: 3 | B36: GV21.TP | D36: 705 | E36: 67 | F36: 1 | I36: =D36*E36*F36/1000000 -> 0.047235 | K36: 1120000 | L36: =ROUND((I36+J36)*K36,0) -> 52903 | M36: tủ kịch trần phải Hồi-
A37: 4 | B37: GV21.TP | D37: 705 | E37: 50 | F37: 1 | J37: =D37/1000*F37 -> 0.705 | K37: 100000 | L37: =ROUND((I37+J37)*K37,0) -> 70500 | M37: tủ kịch trần trái Hồi-
A38: 5 | B38: GV21.TP | D38: 800 | E38: 67 | F38: 1 | I38: =D38*E38*F38/1000000 -> 0.0536 | K38: 1120000 | L38: =ROUND((I38+J38)*K38,0) -> 60032 | M38: tủ trên phải Hồi-
A39: 6 | B39: GV21.TP | D39: 1565 | E39: 600 | F39: 1 | I39: =D39*E39*F39/1000000 -> 0.939 | K39: 1120000 | L39: =ROUND((I39+J39)*K39,0) -> 1051680 | M39: CNC như hình vẽ
A40: 7 | B40: GV21.TP | D40: 1867 | E40: 548 | F40: 1 | I40: =D40*E40*F40/1000000 -> 1.023116 | K40: 1120000 | L40: =ROUND((I40+J40)*K40,0) -> 1145890 | M40: tủ đồ khô Cánh phải-
A41: 8 | B41: GV21.TP | D41: 1136 | E41: 470 | F41: 1 | I41: =D41*E41*F41/1000000 -> 0.53392 | K41: 1120000 | L41: =ROUND((I41+J41)*K41,0) -> 597990 | M41: tủ lạnh Cánh Phải-
A42: 9 | B42: GV21.TP | D42: 1136 | E42: 470 | F42: 1 | I42: =D42*E42*F42/1000000 -> 0.53392 | K42: 1120000 | L42: =ROUND((I42+J42)*K42,0) -> 597990 | M42: tủ lạnh Cánh Trái-
A43: 10 | B43: GV21.TP | D43: 397 | E43: 789 | F43: 1 | G43: =$N$12&N43 -> Vát 789 | I43: =D45*E45*F43/1000000 -> 0.313233 | K43: 1120000 | L43: =ROUND((I43+J43)*K43,0) -> 350821 | M43: tủ trên phải Cánh Phải- | N43: =E45 -> 789 | O43: vát cạnh dài
...

Sheet LENH GIA CONG TAM
F5: LỆNH GIA CÔNG TẤM
F6: ='GIA CONG ACRYLIC'!G6 -> Ngày 23 tháng 6 năm 2026
F7: ='GIA CONG ACRYLIC'!G7 -> Số phiếu: | G7: ='GIA CONG ACRYLIC'!H7 -> L3287
B8: ='GIA CONG ACRYLIC'!C8 -> Khách hàng: KH0457D - Anh Giang Kle (Chinh)
B9: ='GIA CONG ACRYLIC'!C9 -> Địa chỉ: TT Đô Lương 0929903777 - 0989998060
B10: Đề nghị BP Kỹ thuật gia công các sản phẩm dưới đây:
A11: STT | B11: TÊN HÀNG HÓA | C11: Kích thước (mm) | E11: Số lượng | F11: CẠNH VÁT | G11: Chiều vân | H11: Số mét dán thẳng (m) | I11: Số mét dán vát (m) | J11: Số mét vuông (m2) | K11: GHI CHÚ
C12: ='GIA CONG ACRYLIC'!D12 -> Cao (chiều vân gỗ) | D12: Rộng
A13: I | B13: Acrylic màu 1 | E13: =SUM(E14:E32) -> 19 | H13: =SUM(H14:H32) -> 39.347 | I13: =SUM(I14:I32) -> 4.547 | J13: =SUM(J14:J32) -> 3.570451
A14: ='GIA CONG ACRYLIC'!A14 -> 1 | B14: ='GIA CONG ACRYLIC'!C14 -> Cốt MDF, 1 mặt Acrylic GV26 nhũ chống xước cao, 1 mặt acrylic chống cong vênh trắng bóng | C14: ='GIA CONG ACRYLIC'!D14 -> 732 | D14: ='GIA CONG ACRYLIC'!E14 -> 435 | E14: ='GIA CONG ACRYLIC'!F14 -> 1 | F14: ='GIA CONG ACRYLIC'!G14 -> Vát 435 | G14: ='GIA CONG ACRYLIC'!H14 -> 0 | H14: =(C14+D14)*2*E14/1000-I14 -> 1.899 | I14: ='GIA CONG ACRYLIC'!N14*E14/1000 -> 0.435 | J14: =C14*D14*E14/1000000 -> 0.31842 | K14: ='GIA CONG ACRYLIC'!M14 -> tủ dưới phải Cánh Phải-
A15: ='GIA CONG ACRYLIC'!A15 -> 2 | B15: ='GIA CONG ACRYLIC'!C15 -> 0 | C15: ='GIA CONG ACRYLIC'!D15 -> 732 | D15: ='GIA CONG ACRYLIC'!E15 -> 435 | E15: ='GIA CONG ACRYLIC'!F15 -> 1 | F15: ='GIA CONG ACRYLIC'!G15 -> Vát 435 | G15: ='GIA CONG ACRYLIC'!H15 -> 0 | H15: =(C15+D15)*2*E15/1000-I15 -> 1.899 | I15: ='GIA CONG ACRYLIC'!N15*E15/1000 -> 0.435 | J15: =C15*D15*E15/1000000 -> 0.31842 | K15: ='GIA CONG ACRYLIC'!M15 -> tủ dưới phải Cánh Trái-
A16: ='GIA CONG ACRYLIC'!A16 -> 3 | B16: ='GIA CONG ACRYLIC'!C16 -> 0 | C16: ='GIA CONG ACRYLIC'!D16 -> 2182 | D16: ='GIA CONG ACRYLIC'!E16 -> 80 | E16: ='GIA CONG ACRYLIC'!F16 -> 1 | F16: ='GIA CONG ACRYLIC'!G16 -> 0 | G16: ='GIA CONG ACRYLIC'!H16 -> 0 | H16: =(C16+D16)*2*E16/1000-I16 -> 4.524 | I16: ='GIA CONG ACRYLIC'!N16*E16/1000 -> 0 | J16: =C16*D16*E16/1000000 -> 0.17456 | K16: ='GIA CONG ACRYLIC'!M16 -> tủ dưới phải xà trên
A17: ='GIA CONG ACRYLIC'!A17 -> 4 | B17: ='GIA CONG ACRYLIC'!C17 -> 0 | C17: ='GIA CONG ACRYLIC'!D17 -> 800 | D17: ='GIA CONG ACRYLIC'!E17 -> 50 | E17: ='GIA CONG ACRYLIC'!F17 -> 1 | F17: ='GIA CONG ACRYLIC'!G17 -> 0 | G17: ='GIA CONG ACRYLIC'!H17 -> 0 | H17: =(C17+D17)*2*E17/1000-I17 -> 1.7 | I17: ='GIA CONG ACRYLIC'!N17*E17/1000 -> 0 | J17: =C17*D17*E17/1000000 -> 0.04 | K17: ='GIA CONG ACRYLIC'!M17 -> tủ dưới trái Xà
A18: ='GIA CONG ACRYLIC'!A18 -> 5 | B18: ='GIA CONG ACRYLIC'!C18 -> 0 | C18: ='GIA CONG ACRYLIC'!D18 -> 1597 | D18: ='GIA CONG ACRYLIC'!E18 -> 80 | E18: ='GIA CONG ACRYLIC'!F18 -> 1 | F18: ='GIA CONG ACRYLIC'!G18 -> 0 | G18: ='GIA CONG ACRYLIC'!H18 -> 0 | H18: =(C18+D18)*2*E18/1000-I18 -> 3.354 | I18: ='GIA CONG ACRYLIC'!N18*E18/1000 -> 0 | J18: =C18*D18*E18/1000000 -> 0.12776 | K18: ='GIA CONG ACRYLIC'!M18 -> tủ dưới trái xà trên
A19: ='GIA CONG ACRYLIC'!A19 -> 6 | B19: ='GIA CONG ACRYLIC'!C19 -> 0 | C19: ='GIA CONG ACRYLIC'!D19 -> 303 | D19: ='GIA CONG ACRYLIC'!E19 -> 546 | E19: ='GIA CONG ACRYLIC'!F19 -> 1 | F19: ='GIA CONG ACRYLIC'!G19 -> Vát 546 | G19: ='GIA CONG ACRYLIC'!H19 -> 0 | H19: =(C19+D19)*2*E19/1000-I19 -> 1.152 | I19: ='GIA CONG ACRYLIC'!N19*E19/1000 -> 0.546 | J19: =C19*D19*E19/1000000 -> 0.165438 | K19: ='GIA CONG ACRYLIC'!M19 -> tủ đồ khô Mặt Hộc
A20: ='GIA CONG ACRYLIC'!A20 -> 7 | B20: ='GIA CONG ACRYLIC'!C20 -> 0 | C20: ='GIA CONG ACRYLIC'!D20 -> 296 | D20: ='GIA CONG ACRYLIC'!E20 -> 546 | E20: ='GIA CONG ACRYLIC'!F20 -> 1 | F20: ='GIA CONG ACRYLIC'!G20 -> Vát 546 | G20: ='GIA CONG ACRYLIC'!H20 -> 0 | H20: =(C20+D20)*2*E20/1000-I20 -> 1.138 | I20: ='GIA CONG ACRYLIC'!N20*E20/1000 -> 0.546 | J20: =C20*D20*E20/1000000 -> 0.161616 | K20: ='GIA CONG ACRYLIC'!M20 -> tủ đồ khô Mặt Hộc
A21: ='GIA CONG ACRYLIC'!A21 -> 8 | B21: ='GIA CONG ACRYLIC'!C21 -> 0 | C21: ='GIA CONG ACRYLIC'!D21 -> 564 | D21: ='GIA CONG ACRYLIC'!E21 -> 50 | E21: ='GIA CONG ACRYLIC'!F21 -> 1 | F21: ='GIA CONG ACRYLIC'!G21 -> 0 | G21: ='GIA CONG ACRYLIC'!H21 -> 0 | H21: =(C21+D21)*2*E21/1000-I21 -> 1.228 | I21: ='GIA CONG ACRYLIC'!N21*E21/1000 -> 0 | J21: =C21*D21*E21/1000000 -> 0.0282 | K21: ='GIA CONG ACRYLIC'!M21 -> tủ đồ khô Xà
A22: ='GIA CONG ACRYLIC'!A22 -> 9 | B22: ='GIA CONG ACRYLIC'!C22 -> 0 | C22: ='GIA CONG ACRYLIC'!D22 -> 564 | D22: ='GIA CONG ACRYLIC'!E22 -> 50 | E22: ='GIA CONG ACRYLIC'!F22 -> 1 | F22: ='GIA CONG ACRYLIC'!G22 -> 0 | G22: ='GIA CONG ACRYLIC'!H22 -> 0 | H22: =(C22+D22)*2*E22/1000-I22 -> 1.228 | I22: ='GIA CONG ACRYLIC'!N22*E22/1000 -> 0 | J22: =C22*D22*E22/1000000 -> 0.0282 | K22: ='GIA CONG ACRYLIC'!M22 -> tủ đồ khô Xà
A23: ='GIA CONG ACRYLIC'!A23 -> 10 | B23: ='GIA CONG ACRYLIC'!C23 -> 0 | C23: ='GIA CONG ACRYLIC'!D23 -> 834 | D23: ='GIA CONG ACRYLIC'!E23 -> 70 | E23: ='GIA CONG ACRYLIC'!F23 -> 1 | F23: ='GIA CONG ACRYLIC'!G23 -> 0 | G23: ='GIA CONG ACRYLIC'!H23 -> 0 | H23: =(C23+D23)*2*E23/1000-I23 -> 1.808 | I23: ='GIA CONG ACRYLIC'!N23*E23/1000 -> 0 | J23: =C23*D23*E23/1000000 -> 0.05838 | K23: ='GIA CONG ACRYLIC'!M23 -> tủ dưới phải dưới Xà
A24: ='GIA CONG ACRYLIC'!A24 -> 11 | B24: ='GIA CONG ACRYLIC'!C24 -> 0 | C24: ='GIA CONG ACRYLIC'!D24 -> 733 | D24: ='GIA CONG ACRYLIC'!E24 -> 315 | E24: ='GIA CONG ACRYLIC'!F24 -> 1 | F24: ='GIA CONG ACRYLIC'!G24 -> Vát 315 | G24: ='GIA CONG ACRYLIC'!H24 -> 0 | H24: =(C24+D24)*2*E24/1000-I24 -> 1.781 | I24: ='GIA CONG ACRYLIC'!N24*E24/1000 -> 0.315 | J24: =C24*D24*E24/1000000 -> 0.230895 | K24: ='GIA CONG ACRYLIC'!M24 -> tủ dưới phải Mặt Hộc
A25: ='GIA CONG ACRYLIC'!A25 -> 12 | B25: ='GIA CONG ACRYLIC'!C25 -> 0 | C25: ='GIA CONG ACRYLIC'!D25 -> 1492 | D25: ='GIA CONG ACRYLIC'!E25 -> 100 | E25: ='GIA CONG ACRYLIC'!F25 -> 1 | F25: ='GIA CONG ACRYLIC'!G25 -> 0 | G25: ='GIA CONG ACRYLIC'!H25 -> 0 | H25: =(C25+D25)*2*E25/1000-I25 -> 3.184 | I25: ='GIA CONG ACRYLIC'!N25*E25/1000 -> 0 | J25: =C25*D25*E25/1000000 -> 0.1492 | K25: ='GIA CONG ACRYLIC'!M25 -> tủ dưới phải xà chân trước
... A32: ='GIA CONG ACRYLIC'!A32 -> 19 | B32: ='GIA CONG ACRYLIC'!C32 -> 0 | C32: ='GIA CONG ACRYLIC'!D32 -> 1597 | D32: ='GIA CONG ACRYLIC'!E32 -> 100 | E32: ='GIA CONG ACRYLIC'!F32 -> 1 | F32: ='GIA CONG ACRYLIC'!G32 -> 0 | G32: ='GIA CONG ACRYLIC'!H32 -> 0 | H32: =(C32+D32)*2*E32/1000-I32 -> 3.394 | I32: ='GIA CONG ACRYLIC'!N32*E32/1000 -> 0 | J32: =C32*D32*E32/1000000 -> 0.1597 | K32: ='GIA CONG ACRYLIC'!M32 -> tủ dưới trái xà chân trước
A33: ='GIA CONG ACRYLIC'!A33 -> II | B33: ='GIA CONG ACRYLIC'!C33 -> Acrylic màu 2 | E33: ='GIA CONG ACRYLIC'!F33 -> 31 | H33: =SUM(H34:H64) -> 74.24 | I33: =SUM(I34:I64) -> 4.07 | J33: =SUM(J34:J64) -> 9.269163 | K33: ='GIA CONG ACRYLIC'!M33 -> 0
A34: ='GIA CONG ACRYLIC'!A34 -> 1 | B34: ='GIA CONG ACRYLIC'!C34 -> Cốt MDF, 1 mặt Acrylic GV21, 1 mặt acrylic chống cong vênh trắng bóng | C34: ='GIA CONG ACRYLIC'!D34 -> 800 | D34: ='GIA CONG ACRYLIC'!E34 -> 50 | E34: ='GIA CONG ACRYLIC'!F34 -> 1 | F34: ='GIA CONG ACRYLIC'!G34 -> 0 | G34: ='GIA CONG ACRYLIC'!H34 -> 0 | H34: =(C34+D34)*2*E34/1000-I34 -> 1.7 | I34: ='GIA CONG ACRYLIC'!N34*E34/1000 -> 0 | J34: =C34*D34*E34/1000000 -> 0.04 | K34: ='GIA CONG ACRYLIC'!M34 -> tủ dưới trái Hồi-
A35: ='GIA CONG ACRYLIC'!A35 -> 2 | B35: ='GIA CONG ACRYLIC'!C35 -> 0 | C35: ='GIA CONG ACRYLIC'!D35 -> 703 | D35: ='GIA CONG ACRYLIC'!E35 -> 455 | E35: ='GIA CONG ACRYLIC'!F35 -> 1 | F35: ='GIA CONG ACRYLIC'!G35 -> 0 | G35: ='GIA CONG ACRYLIC'!H35 -> 0 | H35: =(C35+D35)*2*E35/1000-I35 -> 2.316 | I35: ='GIA CONG ACRYLIC'!N35*E35/1000 -> 0 | J35: =C35*D35*E35/1000000 -> 0.319865 | K35: ='GIA CONG ACRYLIC'!M35 -> tủ kịch trần phải Cánh phải-
A36: ='GIA CONG ACRYLIC'!A36 -> 3 | B36: ='GIA CONG ACRYLIC'!C36 -> 0 | C36: ='GIA CONG ACRYLIC'!D36 -> 705 | D36: ='GIA CONG ACRYLIC'!E36 -> 67 | E36: ='GIA CONG ACRYLIC'!F36 -> 1 | F36: ='GIA CONG ACRYLIC'!G36 -> 0 | G36: ='GIA CONG ACRYLIC'!H36 -> 0 | H36: =(C36+D36)*2*E36/1000-I36 -> 1.544 | I36: ='GIA CONG ACRYLIC'!N36*E36/1000 -> 0 | J36: =C36*D36*E36/1000000 -> 0.047235 | K36: ='GIA CONG ACRYLIC'!M36 -> tủ kịch trần phải Hồi-
A37: ='GIA CONG ACRYLIC'!A37 -> 4 | B37: ='GIA CONG ACRYLIC'!C37 -> 0 | C37: ='GIA CONG ACRYLIC'!D37 -> 705 | D37: ='GIA CONG ACRYLIC'!E37 -> 50 | E37: ='GIA CONG ACRYLIC'!F37 -> 1 | F37: ='GIA CONG ACRYLIC'!G37 -> 0 | G37: ='GIA CONG ACRYLIC'!H37 -> 0 | H37: =(C37+D37)*2*E37/1000-I37 -> 1.51 | I37: ='GIA CONG ACRYLIC'!N37*E37/1000 -> 0 | J37: =C37*D37*E37/1000000 -> 0.03525 | K37: ='GIA CONG ACRYLIC'!M37 -> tủ kịch trần trái Hồi-
A38: ='GIA CONG ACRYLIC'!A38 -> 5 | B38: ='GIA CONG ACRYLIC'!C38 -> 0 | C38: ='GIA CONG ACRYLIC'!D38 -> 800 | D38: ='GIA CONG ACRYLIC'!E38 -> 67 | E38: ='GIA CONG ACRYLIC'!F38 -> 1 | F38: ='GIA CONG ACRYLIC'!G38 -> 0 | G38: ='GIA CONG ACRYLIC'!H38 -> 0 | H38: =(C38+D38)*2*E38/1000-I38 -> 1.734 | I38: ='GIA CONG ACRYLIC'!N38*E38/1000 -> 0 | J38: =C38*D38*E38/1000000 -> 0.0536 | K38: ='GIA CONG ACRYLIC'!M38 -> tủ trên phải Hồi-
A39: ='GIA CONG ACRYLIC'!A39 -> 6 | B39: ='GIA CONG ACRYLIC'!C39 -> 0 | C39: ='GIA CONG ACRYLIC'!D39 -> 1565 | D39: ='GIA CONG ACRYLIC'!E39 -> 600 | E39: ='GIA CONG ACRYLIC'!F39 -> 1 | F39: ='GIA CONG ACRYLIC'!G39 -> 0 | G39: ='GIA CONG ACRYLIC'!H39 -> 0 | H39: =(C39+D39)*2*E39/1000-I39 -> 4.33 | I39: ='GIA CONG ACRYLIC'!N39*E39/1000 -> 0 | J39: =C39*D39*E39/1000000 -> 0.939 | K39: ='GIA CONG ACRYLIC'!M39 -> CNC như hình vẽ
A40: ='GIA CONG ACRYLIC'!A40 -> 7 | B40: ='GIA CONG ACRYLIC'!C40 -> 0 | C40: ='GIA CONG ACRYLIC'!D40 -> 1867 | D40: ='GIA CONG ACRYLIC'!E40 -> 548 | E40: ='GIA CONG ACRYLIC'!F40 -> 1 | F40: ='GIA CONG ACRYLIC'!G40 -> 0 | G40: ='GIA CONG ACRYLIC'!H40 -> 0 | H40: =(C40+D40)*2*E40/1000-I40 -> 4.83 | I40: ='GIA CONG ACRYLIC'!N40*E40/1000 -> 0 | J40: =C40*D40*E40/1000000 -> 1.023116 | K40: ='GIA CONG ACRYLIC'!M40 -> tủ đồ khô Cánh phải-
A41: ='GIA CONG ACRYLIC'!A41 -> 8 | B41: ='GIA CONG ACRYLIC'!C41 -> 0 | C41: ='GIA CONG ACRYLIC'!D41 -> 1136 | D41: ='GIA CONG ACRYLIC'!E41 -> 470 | E41: ='GIA CONG ACRYLIC'!F41 -> 1 | F41: ='GIA CONG ACRYLIC'!G41 -> 0 | G41: ='GIA CONG ACRYLIC'!H41 -> 0 | H41: =(C41+D41)*2*E41/1000-I41 -> 3.212 | I41: ='GIA CONG ACRYLIC'!N41*E41/1000 -> 0 | J41: =C41*D41*E41/1000000 -> 0.53392 | K41: ='GIA CONG ACRYLIC'!M41 -> tủ lạnh Cánh Phải-
A42: ='GIA CONG ACRYLIC'!A42 -> 9 | B42: ='GIA CONG ACRYLIC'!C42 -> 0 | C42: ='GIA CONG ACRYLIC'!D42 -> 1136 | D42: ='GIA CONG ACRYLIC'!E42 -> 470 | E42: ='GIA CONG ACRYLIC'!F42 -> 1 | F42: ='GIA CONG ACRYLIC'!G42 -> 0 | G42: ='GIA CONG ACRYLIC'!H42 -> 0 | H42: =(C42+D42)*2*E42/1000-I42 -> 3.212 | I42: ='GIA CONG ACRYLIC'!N42*E42/1000 -> 0 | J42: =C42*D42*E42/1000000 -> 0.53392 | K42: ='GIA CONG ACRYLIC'!M42 -> tủ lạnh Cánh Trái-
A43: ='GIA CONG ACRYLIC'!A43 -> 10 | B43: ='GIA CONG ACRYLIC'!C43 -> 0 | C43: ='GIA CONG ACRYLIC'!D43 -> 397 | D43: ='GIA CONG ACRYLIC'!E43 -> 789 | E43: ='GIA CONG ACRYLIC'!F43 -> 1 | F43: ='GIA CONG ACRYLIC'!G43 -> Vát 789 | G43: ='GIA CONG ACRYLIC'!H43 -> 0 | H43: =(C43+D43)*2*E43/1000-I43 -> 1.583 | I43: ='GIA CONG ACRYLIC'!N43*E43/1000 -> 0.789 | J43: =C43*D43*E43/1000000 -> 0.313233 | K43: ='GIA CONG ACRYLIC'!M43 -> tủ trên phải Cánh Phải-
A44: ='GIA CONG ACRYLIC'!A44 -> 11 | B44: ='GIA CONG ACRYLIC'!C44 -> 0 | C44: ='GIA CONG ACRYLIC'!D44 -> 797 | D44: ='GIA CONG ACRYLIC'!E44 -> 389 | E44: ='GIA CONG ACRYLIC'!F44 -> 1 | F44: ='GIA CONG ACRYLIC'!G44 -> Vát 389 | G44: ='GIA CONG ACRYLIC'!H44 -> 0 | H44: =(C44+D44)*2*E44/1000-I44 -> 1.983 | I44: ='GIA CONG ACRYLIC'!N44*E44/1000 -> 0.389 | J44: =C44*D44*E44/1000000 -> 0.310033 | K44: ='GIA CONG ACRYLIC'!M44 -> tủ trên phải Cánh Trái-
A45: ='GIA CONG ACRYLIC'!A45 -> 12 | B45: ='GIA CONG ACRYLIC'!C45 -> 0 | C45: ='GIA CONG ACRYLIC'!D45 -> 397 | D45: ='GIA CONG ACRYLIC'!E45 -> 789 | E45: ='GIA CONG ACRYLIC'!F45 -> 1 | F45: ='GIA CONG ACRYLIC'!G45 -> 0 | G45: ='GIA CONG ACRYLIC'!H45 -> 0 | H45: =(C45+D45)*2*E45/1000-I45 -> 2.372 | I45: ='GIA CONG ACRYLIC'!N45*E45/1000 -> 0 | J45: =C45*D45*E45/1000000 -> 0.313233 | K45: ='GIA CONG ACRYLIC'!M45 -> tủ trên phải Cánh Trái-
... A64: ='GIA CONG ACRYLIC'!A64 -> 31 | B64: ='GIA CONG ACRYLIC'!C64 -> 0 | C64: ='GIA CONG ACRYLIC'!D64 -> 797 | D64: ='GIA CONG ACRYLIC'!E64 -> 386 | E64: ='GIA CONG ACRYLIC'!F64 -> 1 | F64: ='GIA CONG ACRYLIC'!G64 -> Vát 386 | G64: ='GIA CONG ACRYLIC'!H64 -> 0 | H64: =(C64+D64)*2*E64/1000-I64 -> 1.98 | I64: ='GIA CONG ACRYLIC'!N64*E64/1000 -> 0.386 | J64: =C64*D64*E64/1000000 -> 0.307642 | K64: ='GIA CONG ACRYLIC'!M64 -> tủ trên trái Cánh Trái-
B66: Bên giao lệnh | D66: Kế toán | G66: Kỹ thuật | K66: Quản đốc/P.QĐ
B67: (Ký, ghi rõ họ tên) | C67: (Ký, ghi rõ họ tên) | G67: (Ký, ghi rõ họ tên) | K67: (Ký, ghi rõ họ tên)

Sheet DH LEN PHAN MEM
A1: STT | B1: MAHANGHOA | C1: TENHANGHOA | D1: CHIEUDAI | E1: CHIEURONG | F1: SOLUONG | G1: CANHVAT | H1: CHIEUVAN | I1: CANH | J1: THANHPHAO | K1: DONGIA | L1: SOTIENVND | M1: GHICHUND | N1: SODONHANG | O1: KHOILUONG | P1: SOMETDANTHANG | Q1: SOMETDANVAT | R1: NGAYGIOCHOT | S1: SONGAY | T1: NGAYGIAO | U1: SOMETDANMOI | V1: SOMETDANBR1759 | W1: SOMETDANBR2535 | X1: CONGDAN | Y1: SOVATTAYNAMAM | Z1: SOTAMCNC | AA1: DONGIACHI | AB1: DONGIAGIANTHANG | AC1: DONGIAGIANVAT
G5: BÁO GIÁ KIÊM ĐƠN ĐẶT HÀNG
G6: Ngày 17 tháng 4 năm 2022
G7: Số phiếu:
C8: Khách hàng:
C9: Địa chỉ:
C10: Công ty TNHH Gỗ GERVIN xin cảm ơn quý khách hàng đã tin dùng sản phẩm của chúng tôi và xin được báo giá như sau:
A11: Stt | B11: BỔ SUNG MÃ HÀNG | C11: Tên hàng hóa, dịch vụ | D11: Kích thước (mm) | F11: Số lượng | G11: Cạnh vát | H11: Chiều vân | I11: Cánh (m2) | J11: Thanh phào (m) | K11: Đơn giá | L11: Thành tiền | M11: GHI CHÚ | N11: SỐ ĐƠN HÀNG | O11: KHỐI LƯỢNG | P11: Số mét dán thẳng (m) | Q11: Số mét dán vát (m) | R11: Ngày giờ chốt đơn: | S11: Số ngày phải giao từ lúc chốt đơn: | T11: Ngày giờ phải giao hàng:
D12: Cao (chiều vân gỗ) | E12: Rộng
A13: =IF('GIA CONG ACRYLIC'!A13="","",'GIA CONG ACRYLIC'!A13) -> I | B13: =IF('GIA CONG ACRYLIC'!B13="","",'GIA CONG ACRYLIC'!B13) | C13: =IF('GIA CONG ACRYLIC'!C13="","",'GIA CONG ACRYLIC'!C13) -> Acrylic màu 1 | D13: =IF('GIA CONG ACRYLIC'!D13="","",'GIA CONG ACRYLIC'!D13) | E13: =IF('GIA CONG ACRYLIC'!E13="","",'GIA CONG ACRYLIC'!E13) | F13: =IF('GIA CONG ACRYLIC'!F13="","",'GIA CONG ACRYLIC'!F13) -> 19 | G13: =IF('GIA CONG ACRYLIC'!G13="","",'GIA CONG ACRYLIC'!G13) | H13: =IF('GIA CONG ACRYLIC'!H13="","",'GIA CONG ACRYLIC'!H13) | ... M13: =IF('GIA CONG ACRYLIC'!M13="","",'GIA CONG ACRYLIC'!M13) | N13: ='GIA CONG ACRYLIC'!$H$7 -> L3287 | O13: =IF('GIA CONG ACRYLIC'!I13+'GIA CONG ACRYLIC'!J13="","",'GIA CONG ACRYLIC'!I13+'GIA CONG ACRYLIC'!J13) -> 6.100301 | P13: =IF('LENH GIA CONG TAM'!H13="","",'LENH GIA CONG TAM'!H13) -> 39.347 | Q13: =IF('LENH GIA CONG TAM'!I13="","",'LENH GIA CONG TAM'!I13) -> 4.547 | R13: ='GIA CONG ACRYLIC'!$M$6 -> 46196.643 | S13: ='GIA CONG ACRYLIC'!$M$7 -> 2 | T13: ='GIA CONG ACRYLIC'!$M$8 -> 46198.643
A14: =IF('GIA CONG ACRYLIC'!A14="","",'GIA CONG ACRYLIC'!A14) -> 1 | B14: =IF('GIA CONG ACRYLIC'!B14="","",'GIA CONG ACRYLIC'!B14) -> GV26**.TP | C14: =IF('GIA CONG ACRYLIC'!C14="","",'GIA CONG ACRYLIC'!C14) -> Cốt MDF, 1 mặt Acrylic GV26 nhũ chống xước cao, 1 mặt acrylic chống cong vênh trắng bóng | D14: =IF('GIA CONG ACRYLIC'!D14="","",'GIA CONG ACRYLIC'!D14) -> 732 | E14: =IF('GIA CONG ACRYLIC'!E14="","",'GIA CONG ACRYLIC'!E14) -> 435 | F14: =IF('GIA CONG ACRYLIC'!F14="","",'GIA CONG ACRYLIC'!F14) -> 1 | G14: =IF('GIA CONG ACRYLIC'!G14="","",'GIA CONG ACRYLIC'!G14) -> Vát 435 | H14: =IF('GIA CONG ACRYLIC'!H14="","",'GIA CONG ACRYLIC'!H14) | ... M14: =IF('GIA CONG ACRYLIC'!M14="","",'GIA CONG ACRYLIC'!M14) -> tủ dưới phải Cánh Phải- | N14: ='GIA CONG ACRYLIC'!$H$7 -> L3287 | O14: =IF('GIA CONG ACRYLIC'!I14+'GIA CONG ACRYLIC'!J14="","",'GIA CONG ACRYLIC'!I14+'GIA CONG ACRYLIC'!J14) -> 0.31842 | P14: =IF('LENH GIA CONG TAM'!H14="","",'LENH GIA CONG TAM'!H14) -> 1.899 | Q14: =IF('LENH GIA CONG TAM'!I14="","",'LENH GIA CONG TAM'!I14) -> 0.435 | R14: ='GIA CONG ACRYLIC'!$M$6 -> 46196.643 | S14: ='GIA CONG ACRYLIC'!$M$7 -> 2 | T14: ='GIA CONG ACRYLIC'!$M$8 -> 46198.643
A15: =IF('GIA CONG ACRYLIC'!A15="","",'GIA CONG ACRYLIC'!A15) -> 2 | B15: =IF('GIA CONG ACRYLIC'!B15="","",'GIA CONG ACRYLIC'!B15) -> GV26**.TP | C15: =IF('GIA CONG ACRYLIC'!C15="","",'GIA CONG ACRYLIC'!C15) | D15: =IF('GIA CONG ACRYLIC'!D15="","",'GIA CONG ACRYLIC'!D15) -> 732 | E15: =IF('GIA CONG ACRYLIC'!E15="","",'GIA CONG ACRYLIC'!E15) -> 435 | F15: =IF('GIA CONG ACRYLIC'!F15="","",'GIA CONG ACRYLIC'!F15) -> 1 | G15: =IF('GIA CONG ACRYLIC'!G15="","",'GIA CONG ACRYLIC'!G15) -> Vát 435 | H15: =IF('GIA CONG ACRYLIC'!H15="","",'GIA CONG ACRYLIC'!H15) | ... M15: =IF('GIA CONG ACRYLIC'!M15="","",'GIA CONG ACRYLIC'!M15) -> tủ dưới phải Cánh Trái- | N15: ='GIA CONG ACRYLIC'!$H$7 -> L3287 | O15: =IF('GIA CONG ACRYLIC'!I15+'GIA CONG ACRYLIC'!J15="","",'GIA CONG ACRYLIC'!I15+'GIA CONG ACRYLIC'!J15) -> 0.31842 | P15: =IF('LENH GIA CONG TAM'!H15="","",'LENH GIA CONG TAM'!H15) -> 1.899 | Q15: =IF('LENH GIA CONG TAM'!I15="","",'LENH GIA CONG TAM'!I15) -> 0.435 | R15: ='GIA CONG ACRYLIC'!$M$6 -> 46196.643 | S15: ='GIA CONG ACRYLIC'!$M$7 -> 2 | T15: ='GIA CONG ACRYLIC'!$M$8 -> 46198.643
A16: =IF('GIA CONG ACRYLIC'!A30="","",'GIA CONG ACRYLIC'!A30) -> 17 | B16: =IF('GIA CONG ACRYLIC'!B30="","",'GIA CONG ACRYLIC'!B30) -> GV26**.TP | C16: =IF('GIA CONG ACRYLIC'!C30="","",'GIA CONG ACRYLIC'!C30) | D16: =IF('GIA CONG ACRYLIC'!D30="","",'GIA CONG ACRYLIC'!D30) -> 733 | E16: =IF('GIA CONG ACRYLIC'!E30="","",'GIA CONG ACRYLIC'!E30) -> 331 | F16: =IF('GIA CONG ACRYLIC'!F30="","",'GIA CONG ACRYLIC'!F30) -> 1 | G16: =IF('GIA CONG ACRYLIC'!G30="","",'GIA CONG ACRYLIC'!G30) -> Vát 331 | H16: =IF('GIA CONG ACRYLIC'!H30="","",'GIA CONG ACRYLIC'!H30) | ... M16: =IF('GIA CONG ACRYLIC'!M30="","",'GIA CONG ACRYLIC'!M30) -> tủ dưới trái Mặt Hộc | N16: ='GIA CONG ACRYLIC'!$H$7 -> L3287 | O16: =IF('GIA CONG ACRYLIC'!I30+'GIA CONG ACRYLIC'!J30="","",'GIA CONG ACRYLIC'!I30+'GIA CONG ACRYLIC'!J30) -> 0.242623 | P16: =IF('LENH GIA CONG TAM'!H16="","",'LENH GIA CONG TAM'!H16) -> 4.524 | Q16: =IF('LENH GIA CONG TAM'!I16="","",'LENH GIA CONG TAM'!I16) -> 0 | R16: ='GIA CONG ACRYLIC'!$M$6 -> 46196.643 | S16: ='GIA CONG ACRYLIC'!$M$7 -> 2 | T16: ='GIA CONG ACRYLIC'!$M$8 -> 46198.643
A17: =IF('GIA CONG ACRYLIC'!A31="","",'GIA CONG ACRYLIC'!A31) -> 18 | B17: =IF('GIA CONG ACRYLIC'!B31="","",'GIA CONG ACRYLIC'!B31) -> GV26**.TP | C17: =IF('GIA CONG ACRYLIC'!C31="","",'GIA CONG ACRYLIC'!C31) | D17: =IF('GIA CONG ACRYLIC'!D31="","",'GIA CONG ACRYLIC'!D31) -> 735 | E17: =IF('GIA CONG ACRYLIC'!E31="","",'GIA CONG ACRYLIC'!E31) -> 50 | F17: =IF('GIA CONG ACRYLIC'!F31="","",'GIA CONG ACRYLIC'!F31) -> 1 | G17: =IF('GIA CONG ACRYLIC'!G31="","",'GIA CONG ACRYLIC'!G31) | H17: =IF('GIA CONG ACRYLIC'!H31="","",'GIA CONG ACRYLIC'!H31) | ... M17: =IF('GIA CONG ACRYLIC'!M31="","",'GIA CONG ACRYLIC'!M31) -> tủ dưới trái tủ bếp dưới Xà | N17: ='GIA CONG ACRYLIC'!$H$7 -> L3287 | O17: =IF('GIA CONG ACRYLIC'!I31+'GIA CONG ACRYLIC'!J31="","",'GIA CONG ACRYLIC'!I31+'GIA CONG ACRYLIC'!J31) -> 0.735 | P17: =IF('LENH GIA CONG TAM'!H17="","",'LENH GIA CONG TAM'!H17) -> 1.7 | Q17: =IF('LENH GIA CONG TAM'!I17="","",'LENH GIA CONG TAM'!I17) -> 0 | R17: ='GIA CONG ACRYLIC'!$M$6 -> 46196.643 | S17: ='GIA CONG ACRYLIC'!$M$7 -> 2 | T17: ='GIA CONG ACRYLIC'!$M$8 -> 46198.643
A18: =IF('GIA CONG ACRYLIC'!A32="","",'GIA CONG ACRYLIC'!A32) -> 19 | B18: =IF('GIA CONG ACRYLIC'!B32="","",'GIA CONG ACRYLIC'!B32) -> GV26**.TP | C18: =IF('GIA CONG ACRYLIC'!C32="","",'GIA CONG ACRYLIC'!C32) | D18: =IF('GIA CONG ACRYLIC'!D32="","",'GIA CONG ACRYLIC'!D32) -> 1597 | E18: =IF('GIA CONG ACRYLIC'!E32="","",'GIA CONG ACRYLIC'!E32) -> 100 | F18: =IF('GIA CONG ACRYLIC'!F32="","",'GIA CONG ACRYLIC'!F32) -> 1 | G18: =IF('GIA CONG ACRYLIC'!G32="","",'GIA CONG ACRYLIC'!G32) | H18: =IF('GIA CONG ACRYLIC'!H32="","",'GIA CONG ACRYLIC'!H32) | ... M18: =IF('GIA CONG ACRYLIC'!M32="","",'GIA CONG ACRYLIC'!M32) -> tủ dưới trái xà chân trước | N18: ='GIA CONG ACRYLIC'!$H$7 -> L3287 | O18: =IF('GIA CONG ACRYLIC'!I32+'GIA CONG ACRYLIC'!J32="","",'GIA CONG ACRYLIC'!I32+'GIA CONG ACRYLIC'!J32) -> 0.1597 | P18: =IF('LENH GIA CONG TAM'!H18="","",'LENH GIA CONG TAM'!H18) -> 3.354 | Q18: =IF('LENH GIA CONG TAM'!I18="","",'LENH GIA CONG TAM'!I18) -> 0 | R18: ='GIA CONG ACRYLIC'!$M$6 -> 46196.643 | S18: ='GIA CONG ACRYLIC'!$M$7 -> 2 | T18: ='GIA CONG ACRYLIC'!$M$8 -> 46198.643
A19: =IF('GIA CONG ACRYLIC'!A33="","",'GIA CONG ACRYLIC'!A33) -> II | B19: =IF('GIA CONG ACRYLIC'!B33="","",'GIA CONG ACRYLIC'!B33) | C19: =IF('GIA CONG ACRYLIC'!C33="","",'GIA CONG ACRYLIC'!C33) -> Acrylic màu 2 | D19: =IF('GIA CONG ACRYLIC'!D33="","",'GIA CONG ACRYLIC'!D33) | E19: =IF('GIA CONG ACRYLIC'!E33="","",'GIA CONG ACRYLIC'!E33) | F19: =IF('GIA CONG ACRYLIC'!F33="","",'GIA CONG ACRYLIC'!F33) -> 31 | G19: =IF('GIA CONG ACRYLIC'!G33="","",'GIA CONG ACRYLIC'!G33) | H19: =IF('GIA CONG ACRYLIC'!H33="","",'GIA CONG ACRYLIC'!H33) | ... M19: =IF('GIA CONG ACRYLIC'!M33="","",'GIA CONG ACRYLIC'!M33) | N19: ='GIA CONG ACRYLIC'!$H$7 -> L3287 | O19: =IF('GIA CONG ACRYLIC'!I33+'GIA CONG ACRYLIC'!J33="","",'GIA CONG ACRYLIC'!I33+'GIA CONG ACRYLIC'!J33) -> 10.698913 | P19: =IF('LENH GIA CONG TAM'!H19="","",'LENH GIA CONG TAM'!H19) -> 1.152 | Q19: =IF('LENH GIA CONG TAM'!I19="","",'LENH GIA CONG TAM'!I19) -> 0.546 | R19: ='GIA CONG ACRYLIC'!$M$6 -> 46196.643 | S19: ='GIA CONG ACRYLIC'!$M$7 -> 2 | T19: ='GIA CONG ACRYLIC'!$M$8 -> 46198.643
A20: =IF('GIA CONG ACRYLIC'!A34="","",'GIA CONG ACRYLIC'!A34) -> 1 | B20: =IF('GIA CONG ACRYLIC'!B34="","",'GIA CONG ACRYLIC'!B34) -> GV21.TP | C20: =IF('GIA CONG ACRYLIC'!C34="","",'GIA CONG ACRYLIC'!C34) -> Cốt MDF, 1 mặt Acrylic GV21, 1 mặt acrylic chống cong vênh trắng bóng | D20: =IF('GIA CONG ACRYLIC'!D34="","",'GIA CONG ACRYLIC'!D34) -> 800 | E20: =IF('GIA CONG ACRYLIC'!E34="","",'GIA CONG ACRYLIC'!E34) -> 50 | F20: =IF('GIA CONG ACRYLIC'!F34="","",'GIA CONG ACRYLIC'!F34) -> 1 | G20: =IF('GIA CONG ACRYLIC'!G34="","",'GIA CONG ACRYLIC'!G34) | H20: =IF('GIA CONG ACRYLIC'!H34="","",'GIA CONG ACRYLIC'!H34) | ... M20: =IF('GIA CONG ACRYLIC'!M34="","",'GIA CONG ACRYLIC'!M34) -> tủ dưới trái Hồi- | N20: ='GIA CONG ACRYLIC'!$H$7 -> L3287 | O20: =IF('GIA CONG ACRYLIC'!I34+'GIA CONG ACRYLIC'!J34="","",'GIA CONG ACRYLIC'!I34+'GIA CONG ACRYLIC'!J34) -> 0.8 | P20: =IF('LENH GIA CONG TAM'!H20="","",'LENH GIA CONG TAM'!H20) -> 1.138 | Q20: =IF('LENH GIA CONG TAM'!I20="","",'LENH GIA CONG TAM'!I20) -> 0.546 | R20: ='GIA CONG ACRYLIC'!$M$6 -> 46196.643 | S20: ='GIA CONG ACRYLIC'!$M$7 -> 2 | T20: ='GIA CONG ACRYLIC'!$M$8 -> 46198.643
A21: =IF('GIA CONG ACRYLIC'!#REF!="","",'GIA CONG ACRYLIC'!#REF!) -> #REF! | B21: =IF('GIA CONG ACRYLIC'!#REF!="","",'GIA CONG ACRYLIC'!#REF!) -> #REF! | C21: =IF('GIA CONG ACRYLIC'!#REF!="","",'GIA CONG ACRYLIC'!#REF!) -> #REF! | D21: =IF('GIA CONG ACRYLIC'!#REF!="","",'GIA CONG ACRYLIC'!#REF!) -> #REF! | E21: =IF('GIA CONG ACRYLIC'!#REF!="","",'GIA CONG ACRYLIC'!#REF!) -> #REF! | F21: =IF('GIA CONG ACRYLIC'!#REF!="","",'GIA CONG ACRYLIC'!#REF!) -> #REF! | G21: =IF('GIA CONG ACRYLIC'!#REF!="","",'GIA CONG ACRYLIC'!#REF!) -> #REF! | H21: =IF('GIA CONG ACRYLIC'!#REF!="","",'GIA CONG ACRYLIC'!#REF!) -> #REF! | ... M21: =IF('GIA CONG ACRYLIC'!#REF!="","",'GIA CONG ACRYLIC'!#REF!) -> #REF! | N21: ='GIA CONG ACRYLIC'!$H$7 -> L3287 | O21: =IF('GIA CONG ACRYLIC'!#REF!+'GIA CONG ACRYLIC'!#REF!="","",'GIA CONG ACRYLIC'!#REF!+'GIA CONG ACRYLIC'!#REF!) -> #REF! | P21: =IF('LENH GIA CONG TAM'!#REF!="","",'LENH GIA CONG TAM'!#REF!) -> #REF! | Q21: =IF('LENH GIA CONG TAM'!#REF!="","",'LENH GIA CONG TAM'!#REF!) -> #REF! | R21: ='GIA CONG ACRYLIC'!$M$6 -> 46196.643 | S21: ='GIA CONG ACRYLIC'!$M$7 -> 2 | T21: ='GIA CONG ACRYLIC'!$M$8 -> 46198.643
A22: =IF('GIA CONG ACRYLIC'!#REF!="","",'GIA CONG ACRYLIC'!#REF!) -> #REF! | B22: =IF('GIA CONG ACRYLIC'!#REF!="","",'GIA CONG ACRYLIC'!#REF!) -> #REF! | C22: =IF('GIA CONG ACRYLIC'!#REF!="","",'GIA CONG ACRYLIC'!#REF!) -> #REF! | D22: =IF('GIA CONG ACRYLIC'!#REF!="","",'GIA CONG ACRYLIC'!#REF!) -> #REF! | E22: =IF('GIA CONG ACRYLIC'!#REF!="","",'GIA CONG ACRYLIC'!#REF!) -> #REF! | F22: =IF('GIA CONG ACRYLIC'!#REF!="","",'GIA CONG ACRYLIC'!#REF!) -> #REF! | G22: =IF('GIA CONG ACRYLIC'!#REF!="","",'GIA CONG ACRYLIC'!#REF!) -> #REF! | H22: =IF('GIA CONG ACRYLIC'!#REF!="","",'GIA CONG ACRYLIC'!#REF!) -> #REF! | ... M22: =IF('GIA CONG ACRYLIC'!#REF!="","",'GIA CONG ACRYLIC'!#REF!) -> #REF! | N22: ='GIA CONG ACRYLIC'!$H$7 -> L3287 | O22: =IF('GIA CONG ACRYLIC'!#REF!+'GIA CONG ACRYLIC'!#REF!="","",'GIA CONG ACRYLIC'!#REF!+'GIA CONG ACRYLIC'!#REF!) -> #REF! | P22: =IF('LENH GIA CONG TAM'!#REF!="","",'LENH GIA CONG TAM'!#REF!) -> #REF! | Q22: =IF('LENH GIA CONG TAM'!#REF!="","",'LENH GIA CONG TAM'!#REF!) -> #REF! | R22: ='GIA CONG ACRYLIC'!$M$6 -> 46196.643 | S22: ='GIA CONG ACRYLIC'!$M$7 -> 2 | T22: ='GIA CONG ACRYLIC'!$M$8 -> 46198.643
A23: =IF('GIA CONG ACRYLIC'!#REF!="","",'GIA CONG ACRYLIC'!#REF!) -> #REF! | B23: =IF('GIA CONG ACRYLIC'!#REF!="","",'GIA CONG ACRYLIC'!#REF!) -> #REF! | C23: =IF('GIA CONG ACRYLIC'!#REF!="","",'GIA CONG ACRYLIC'!#REF!) -> #REF! | D23: =IF('GIA CONG ACRYLIC'!#REF!="","",'GIA CONG ACRYLIC'!#REF!) -> #REF! | E23: =IF('GIA CONG ACRYLIC'!#REF!="","",'GIA CONG ACRYLIC'!#REF!) -> #REF! | F23: =IF('GIA CONG ACRYLIC'!#REF!="","",'GIA CONG ACRYLIC'!#REF!) -> #REF! | G23: =IF('GIA CONG ACRYLIC'!#REF!="","",'GIA CONG ACRYLIC'!#REF!) -> #REF! | H23: =IF('GIA CONG ACRYLIC'!#REF!="","",'GIA CONG ACRYLIC'!#REF!) -> #REF! | ... M23: =IF('GIA CONG ACRYLIC'!#REF!="","",'GIA CONG ACRYLIC'!#REF!) -> #REF! | N23: ='GIA CONG ACRYLIC'!$H$7 -> L3287 | O23: =IF('GIA CONG ACRYLIC'!#REF!+'GIA CONG ACRYLIC'!#REF!="","",'GIA CONG ACRYLIC'!#REF!+'GIA CONG ACRYLIC'!#REF!) -> #REF! | P23: =IF('LENH GIA CONG TAM'!#REF!="","",'LENH GIA CONG TAM'!#REF!) -> #REF! | Q23: =IF('LENH GIA CONG TAM'!#REF!="","",'LENH GIA CONG TAM'!#REF!) -> #REF! | R23: ='GIA CONG ACRYLIC'!$M$6 -> 46196.643 | S23: ='GIA CONG ACRYLIC'!$M$7 -> 2 | T23: ='GIA CONG ACRYLIC'!$M$8 -> 46198.643
A24: =IF('GIA CONG ACRYLIC'!#REF!="","",'GIA CONG ACRYLIC'!#REF!) -> #REF! | B24: =IF('GIA CONG ACRYLIC'!#REF!="","",'GIA CONG ACRYLIC'!#REF!) -> #REF! | C24: =IF('GIA CONG ACRYLIC'!#REF!="","",'GIA CONG ACRYLIC'!#REF!) -> #REF! | D24: =IF('GIA CONG ACRYLIC'!#REF!="","",'GIA CONG ACRYLIC'!#REF!) -> #REF! | E24: =IF('GIA CONG ACRYLIC'!#REF!="","",'GIA CONG ACRYLIC'!#REF!) -> #REF! | F24: =IF('GIA CONG ACRYLIC'!#REF!="","",'GIA CONG ACRYLIC'!#REF!) -> #REF! | G24: =IF('GIA CONG ACRYLIC'!#REF!="","",'GIA CONG ACRYLIC'!#REF!) -> #REF! | H24: =IF('GIA CONG ACRYLIC'!#REF!="","",'GIA CONG ACRYLIC'!#REF!) -> #REF! | ... M24: =IF('GIA CONG ACRYLIC'!#REF!="","",'GIA CONG ACRYLIC'!#REF!) -> #REF! | N24: ='GIA CONG ACRYLIC'!$H$7 -> L3287 | O24: =IF('GIA CONG ACRYLIC'!#REF!+'GIA CONG ACRYLIC'!#REF!="","",'GIA CONG ACRYLIC'!#REF!+'GIA CONG ACRYLIC'!#REF!) -> #REF! | P24: =IF('LENH GIA CONG TAM'!#REF!="","",'LENH GIA CONG TAM'!#REF!) -> #REF! | Q24: =IF('LENH GIA CONG TAM'!#REF!="","",'LENH GIA CONG TAM'!#REF!) -> #REF! | R24: ='GIA CONG ACRYLIC'!$M$6 -> 46196.643 | S24: ='GIA CONG ACRYLIC'!$M$7 -> 2 | T24: ='GIA CONG ACRYLIC'!$M$8 -> 46198.643
A25: =IF('GIA CONG ACRYLIC'!#REF!="","",'GIA CONG ACRYLIC'!#REF!) -> #REF! | B25: =IF('GIA CONG ACRYLIC'!#REF!="","",'GIA CONG ACRYLIC'!#REF!) -> #REF! | C25: =IF('GIA CONG ACRYLIC'!#REF!="","",'GIA CONG ACRYLIC'!#REF!) -> #REF! | D25: =IF('GIA CONG ACRYLIC'!#REF!="","",'GIA CONG ACRYLIC'!#REF!) -> #REF! | E25: =IF('GIA CONG ACRYLIC'!#REF!="","",'GIA CONG ACRYLIC'!#REF!) -> #REF! | F25: =IF('GIA CONG ACRYLIC'!#REF!="","",'GIA CONG ACRYLIC'!#REF!) -> #REF! | G25: =IF('GIA CONG ACRYLIC'!#REF!="","",'GIA CONG ACRYLIC'!#REF!) -> #REF! | H25: =IF('GIA CONG ACRYLIC'!#REF!="","",'GIA CONG ACRYLIC'!#REF!) -> #REF! | ... M25: =IF('GIA CONG ACRYLIC'!#REF!="","",'GIA CONG ACRYLIC'!#REF!) -> #REF! | N25: ='GIA CONG ACRYLIC'!$H$7 -> L3287 | O25: =IF('GIA CONG ACRYLIC'!#REF!+'GIA CONG ACRYLIC'!#REF!="","",'GIA CONG ACRYLIC'!#REF!+'GIA CONG ACRYLIC'!#REF!) -> #REF! | P25: =IF('LENH GIA CONG TAM'!#REF!="","",'LENH GIA CONG TAM'!#REF!) -> #REF! | Q25: =IF('LENH GIA CONG TAM'!#REF!="","",'LENH GIA CONG TAM'!#REF!) -> #REF! | R25: ='GIA CONG ACRYLIC'!$M$6 -> 46196.643 | S25: ='GIA CONG ACRYLIC'!$M$7 -> 2 | T25: ='GIA CONG ACRYLIC'!$M$8 -> 46198.643
A26: =IF('GIA CONG ACRYLIC'!#REF!="","",'GIA CONG ACRYLIC'!#REF!) -> #REF! | B26: =IF('GIA CONG ACRYLIC'!#REF!="","",'GIA CONG ACRYLIC'!#REF!) -> #REF! | C26: =IF('GIA CONG ACRYLIC'!#REF!="","",'GIA CONG ACRYLIC'!#REF!) -> #REF! | D26: =IF('GIA CONG ACRYLIC'!#REF!="","",'GIA CONG ACRYLIC'!#REF!) -> #REF! | E26: =IF('GIA CONG ACRYLIC'!#REF!="","",'GIA CONG ACRYLIC'!#REF!) -> #REF! | F26: =IF('GIA CONG ACRYLIC'!#REF!="","",'GIA CONG ACRYLIC'!#REF!) -> #REF! | G26: =IF('GIA CONG ACRYLIC'!#REF!="","",'GIA CONG ACRYLIC'!#REF!) -> #REF! | H26: =IF('GIA CONG ACRYLIC'!#REF!="","",'GIA CONG ACRYLIC'!#REF!) -> #REF! | ... M26: =IF('GIA CONG ACRYLIC'!#REF!="","",'GIA CONG ACRYLIC'!#REF!) -> #REF! | N26: ='GIA CONG ACRYLIC'!$H$7 -> L3287 | O26: =IF('GIA CONG ACRYLIC'!#REF!+'GIA CONG ACRYLIC'!#REF!="","",'GIA CONG ACRYLIC'!#REF!+'GIA CONG ACRYLIC'!#REF!) -> #REF! | P26: =IF('LENH GIA CONG TAM'!#REF!="","",'LENH GIA CONG TAM'!#REF!) -> #REF! | Q26: =IF('LENH GIA CONG TAM'!#REF!="","",'LENH GIA CONG TAM'!#REF!) -> #REF! | R26: ='GIA CONG ACRYLIC'!$M$6 -> 46196.643 | S26: ='GIA CONG ACRYLIC'!$M$7 -> 2 | T26: ='GIA CONG ACRYLIC'!$M$8 -> 46198.643
A27: =IF('GIA CONG ACRYLIC'!#REF!="","",'GIA CONG ACRYLIC'!#REF!) -> #REF! | B27: =IF('GIA CONG ACRYLIC'!#REF!="","",'GIA CONG ACRYLIC'!#REF!) -> #REF! | C27: =IF('GIA CONG ACRYLIC'!#REF!="","",'GIA CONG ACRYLIC'!#REF!) -> #REF! | D27: =IF('GIA CONG ACRYLIC'!#REF!="","",'GIA CONG ACRYLIC'!#REF!) -> #REF! | E27: =IF('GIA CONG ACRYLIC'!#REF!="","",'GIA CONG ACRYLIC'!#REF!) -> #REF! | F27: =IF('GIA CONG ACRYLIC'!#REF!="","",'GIA CONG ACRYLIC'!#REF!) -> #REF! | G27: =IF('GIA CONG ACRYLIC'!#REF!="","",'GIA CONG ACRYLIC'!#REF!) -> #REF! | H27: =IF('GIA CONG ACRYLIC'!#REF!="","",'GIA CONG ACRYLIC'!#REF!) -> #REF! | ... M27: =IF('GIA CONG ACRYLIC'!#REF!="","",'GIA CONG ACRYLIC'!#REF!) -> #REF! | N27: ='GIA CONG ACRYLIC'!$H$7 -> L3287 | O27: =IF('GIA CONG ACRYLIC'!#REF!+'GIA CONG ACRYLIC'!#REF!="","",'GIA CONG ACRYLIC'!#REF!+'GIA CONG ACRYLIC'!#REF!) -> #REF! | P27: =IF('LENH GIA CONG TAM'!#REF!="","",'LENH GIA CONG TAM'!#REF!) -> #REF! | Q27: =IF('LENH GIA CONG TAM'!#REF!="","",'LENH GIA CONG TAM'!#REF!) -> #REF! | R27: ='GIA CONG ACRYLIC'!$M$6 -> 46196.643 | S27: ='GIA CONG ACRYLIC'!$M$7 -> 2 | T27: ='GIA CONG ACRYLIC'!$M$8 -> 46198.643
A28: =IF('GIA CONG ACRYLIC'!#REF!="","",'GIA CONG ACRYLIC'!#REF!) -> #REF! | B28: =IF('GIA CONG ACRYLIC'!#REF!="","",'GIA CONG ACRYLIC'!#REF!) -> #REF! | C28: =IF('GIA CONG ACRYLIC'!#REF!="","",'GIA CONG ACRYLIC'!#REF!) -> #REF! | D28: =IF('GIA CONG ACRYLIC'!#REF!="","",'GIA CONG ACRYLIC'!#REF!) -> #REF! | E28: =IF('GIA CONG ACRYLIC'!#REF!="","",'GIA CONG ACRYLIC'!#REF!) -> #REF! | F28: =IF('GIA CONG ACRYLIC'!#REF!="","",'GIA CONG ACRYLIC'!#REF!) -> #REF! | G28: =IF('GIA CONG ACRYLIC'!#REF!="","",'GIA CONG ACRYLIC'!#REF!) -> #REF! | H28: =IF('GIA CONG ACRYLIC'!#REF!="","",'GIA CONG ACRYLIC'!#REF!) -> #REF! | ... M28: =IF('GIA CONG ACRYLIC'!#REF!="","",'GIA CONG ACRYLIC'!#REF!) -> #REF! | N28: ='GIA CONG ACRYLIC'!$H$7 -> L3287 | O28: =IF('GIA CONG ACRYLIC'!#REF!+'GIA CONG ACRYLIC'!#REF!="","",'GIA CONG ACRYLIC'!#REF!+'GIA CONG ACRYLIC'!#REF!) -> #REF! | P28: =IF('LENH GIA CONG TAM'!#REF!="","",'LENH GIA CONG TAM'!#REF!) -> #REF! | Q28: =IF('LENH GIA CONG TAM'!#REF!="","",'LENH GIA CONG TAM'!#REF!) -> #REF! | R28: ='GIA CONG ACRYLIC'!$M$6 -> 46196.643 | S28: ='GIA CONG ACRYLIC'!$M$7 -> 2 | T28: ='GIA CONG ACRYLIC'!$M$8 -> 46198.643
A29: =IF('GIA CONG ACRYLIC'!#REF!="","",'GIA CONG ACRYLIC'!#REF!) -> #REF! | B29: =IF('GIA CONG ACRYLIC'!#REF!="","",'GIA CONG ACRYLIC'!#REF!) -> #REF! | C29: =IF('GIA CONG ACRYLIC'!#REF!="","",'GIA CONG ACRYLIC'!#REF!) -> #REF! | D29: =IF('GIA CONG ACRYLIC'!#REF!="","",'GIA CONG ACRYLIC'!#REF!) -> #REF! | E29: =IF('GIA CONG ACRYLIC'!#REF!="","",'GIA CONG ACRYLIC'!#REF!) -> #REF! | F29: =IF('GIA CONG ACRYLIC'!#REF!="","",'GIA CONG ACRYLIC'!#REF!) -> #REF! | G29: =IF('GIA CONG ACRYLIC'!#REF!="","",'GIA CONG ACRYLIC'!#REF!) -> #REF! | H29: =IF('GIA CONG ACRYLIC'!#REF!="","",'GIA CONG ACRYLIC'!#REF!) -> #REF! | ... M29: =IF('GIA CONG ACRYLIC'!#REF!="","",'GIA CONG ACRYLIC'!#REF!) -> #REF! | N29: ='GIA CONG ACRYLIC'!$H$7 -> L3287 | O29: =IF('GIA CONG ACRYLIC'!#REF!+'GIA CONG ACRYLIC'!#REF!="","",'GIA CONG ACRYLIC'!#REF!+'GIA CONG ACRYLIC'!#REF!) -> #REF! | P29: =IF('LENH GIA CONG TAM'!#REF!="","",'LENH GIA CONG TAM'!#REF!) -> #REF! | Q29: =IF('LENH GIA CONG TAM'!#REF!="","",'LENH GIA CONG TAM'!#REF!) -> #REF! | R29: ='GIA CONG ACRYLIC'!$M$6 -> 46196.643 | S29: ='GIA CONG ACRYLIC'!$M$7 -> 2 | T29: ='GIA CONG ACRYLIC'!$M$8 -> 46198.643
A30: =IF('GIA CONG ACRYLIC'!#REF!="","",'GIA CONG ACRYLIC'!#REF!) -> #REF! | B30: =IF('GIA CONG ACRYLIC'!#REF!="","",'GIA CONG ACRYLIC'!#REF!) -> #REF! | C30: =IF('GIA CONG ACRYLIC'!#REF!="","",'GIA CONG ACRYLIC'!#REF!) -> #REF! | D30: =IF('GIA CONG ACRYLIC'!#REF!="","",'GIA CONG ACRYLIC'!#REF!) -> #REF! | E30: =IF('GIA CONG ACRYLIC'!#REF!="","",'GIA CONG ACRYLIC'!#REF!) -> #REF! | F30: =IF('GIA CONG ACRYLIC'!#REF!="","",'GIA CONG ACRYLIC'!#REF!) -> #REF! | G30: =IF('GIA CONG ACRYLIC'!#REF!="","",'GIA CONG ACRYLIC'!#REF!) -> #REF! | H30: =IF('GIA CONG ACRYLIC'!#REF!="","",'GIA CONG ACRYLIC'!#REF!) -> #REF! | ... M30: =IF('GIA CONG ACRYLIC'!#REF!="","",'GIA CONG ACRYLIC'!#REF!) -> #REF! | N30: ='GIA CONG ACRYLIC'!$H$7 -> L3287 | O30: =IF('GIA CONG ACRYLIC'!#REF!+'GIA CONG ACRYLIC'!#REF!="","",'GIA CONG ACRYLIC'!#REF!+'GIA CONG ACRYLIC'!#REF!) -> #REF! | P30: =IF('LENH GIA CONG TAM'!#REF!="","",'LENH GIA CONG TAM'!#REF!) -> #REF! | Q30: =IF('LENH GIA CONG TAM'!#REF!="","",'LENH GIA CONG TAM'!#REF!) -> #REF! | R30: ='GIA CONG ACRYLIC'!$M$6 -> 46196.643 | S30: ='GIA CONG ACRYLIC'!$M$7 -> 2 | T30: ='GIA CONG ACRYLIC'!$M$8 -> 46198.643
A31: =IF('GIA CONG ACRYLIC'!#REF!="","",'GIA CONG ACRYLIC'!#REF!) -> #REF! | B31: =IF('GIA CONG ACRYLIC'!#REF!="","",'GIA CONG ACRYLIC'!#REF!) -> #REF! | C31: =IF('GIA CONG ACRYLIC'!#REF!="","",'GIA CONG ACRYLIC'!#REF!) -> #REF! | D31: =IF('GIA CONG ACRYLIC'!#REF!="","",'GIA CONG ACRYLIC'!#REF!) -> #REF! | E31: =IF('GIA CONG ACRYLIC'!#REF!="","",'GIA CONG ACRYLIC'!#REF!) -> #REF! | F31: =IF('GIA CONG ACRYLIC'!#REF!="","",'GIA CONG ACRYLIC'!#REF!) -> #REF! | G31: =IF('GIA CONG ACRYLIC'!#REF!="","",'GIA CONG ACRYLIC'!#REF!) -> #REF! | H31: =IF('GIA CONG ACRYLIC'!#REF!="","",'GIA CONG ACRYLIC'!#REF!) -> #REF! | ... M31: =IF('GIA CONG ACRYLIC'!#REF!="","",'GIA CONG ACRYLIC'!#REF!) -> #REF! | N31: ='GIA CONG ACRYLIC'!$H$7 -> L3287 | O31: =IF('GIA CONG ACRYLIC'!#REF!+'GIA CONG ACRYLIC'!#REF!="","",'GIA CONG ACRYLIC'!#REF!+'GIA CONG ACRYLIC'!#REF!) -> #REF! | P31: =IF('LENH GIA CONG TAM'!#REF!="","",'LENH GIA CONG TAM'!#REF!) -> #REF! | Q31: =IF('LENH GIA CONG TAM'!#REF!="","",'LENH GIA CONG TAM'!#REF!) -> #REF! | R31: ='GIA CONG ACRYLIC'!$M$6 -> 46196.643 | S31: ='GIA CONG ACRYLIC'!$M$7 -> 2 | T31: ='GIA CONG ACRYLIC'!$M$8 -> 46198.643
A32: =IF('GIA CONG ACRYLIC'!#REF!="","",'GIA CONG ACRYLIC'!#REF!) -> #REF! | B32: =IF('GIA CONG ACRYLIC'!#REF!="","",'GIA CONG ACRYLIC'!#REF!) -> #REF! | C32: =IF('GIA CONG ACRYLIC'!#REF!="","",'GIA CONG ACRYLIC'!#REF!) -> #REF! | D32: =IF('GIA CONG ACRYLIC'!#REF!="","",'GIA CONG ACRYLIC'!#REF!) -> #REF! | E32: =IF('GIA CONG ACRYLIC'!#REF!="","",'GIA CONG ACRYLIC'!#REF!) -> #REF! | F32: =IF('GIA CONG ACRYLIC'!#REF!="","",'GIA CONG ACRYLIC'!#REF!) -> #REF! | G32: =IF('GIA CONG ACRYLIC'!#REF!="","",'GIA CONG ACRYLIC'!#REF!) -> #REF! | H32: =IF('GIA CONG ACRYLIC'!#REF!="","",'GIA CONG ACRYLIC'!#REF!) -> #REF! | ... M32: =IF('GIA CONG ACRYLIC'!#REF!="","",'GIA CONG ACRYLIC'!#REF!) -> #REF! | N32: ='GIA CONG ACRYLIC'!$H$7 -> L3287 | O32: =IF('GIA CONG ACRYLIC'!#REF!+'GIA CONG ACRYLIC'!#REF!="","",'GIA CONG ACRYLIC'!#REF!+'GIA CONG ACRYLIC'!#REF!) -> #REF! | P32: =IF('LENH GIA CONG TAM'!#REF!="","",'LENH GIA CONG TAM'!#REF!) -> #REF! | Q32: =IF('LENH GIA CONG TAM'!#REF!="","",'LENH GIA CONG TAM'!#REF!) -> #REF! | R32: ='GIA CONG ACRYLIC'!$M$6 -> 46196.643 | S32: ='GIA CONG ACRYLIC'!$M$7 -> 2 | T32: ='GIA CONG ACRYLIC'!$M$8 -> 46198.643
A33: =IF('GIA CONG ACRYLIC'!A65="","",'GIA CONG ACRYLIC'!A65) | B33: =IF('GIA CONG ACRYLIC'!B65="","",'GIA CONG ACRYLIC'!B65) | C33: =IF('GIA CONG ACRYLIC'!C65="","",'GIA CONG ACRYLIC'!C65) | D33: =IF('GIA CONG ACRYLIC'!D65="","",'GIA CONG ACRYLIC'!D65) | E33: =IF('GIA CONG ACRYLIC'!E65="","",'GIA CONG ACRYLIC'!E65) | F33: =IF('GIA CONG ACRYLIC'!F65="","",'GIA CONG ACRYLIC'!F65) -> 50 | G33: =IF('GIA CONG ACRYLIC'!G65="","",'GIA CONG ACRYLIC'!G65) | H33: =IF('GIA CONG ACRYLIC'!H65="","",'GIA CONG ACRYLIC'!H65) | ... M33: =IF('GIA CONG ACRYLIC'!M65="","",'GIA CONG ACRYLIC'!M65) | N33: ='GIA CONG ACRYLIC'!$H$7 -> L3287 | O33: =IF('GIA CONG ACRYLIC'!I65+'GIA CONG ACRYLIC'!J65="","",'GIA CONG ACRYLIC'!I65+'GIA CONG ACRYLIC'!J65) -> 16.799214 | P33: =IF('LENH GIA CONG TAM'!H21="","",'LENH GIA CONG TAM'!H21) -> 1.228 | Q33: =IF('LENH GIA CONG TAM'!I21="","",'LENH GIA CONG TAM'!I21) -> 0 | R33: ='GIA CONG ACRYLIC'!$M$6 -> 46196.643 | S33: ='GIA CONG ACRYLIC'!$M$7 -> 2 | T33: ='GIA CONG ACRYLIC'!$M$8 -> 46198.643
A34: =IF('GIA CONG ACRYLIC'!#REF!="","",'GIA CONG ACRYLIC'!#REF!) -> #REF! | B34: =IF('GIA CONG ACRYLIC'!#REF!="","",'GIA CONG ACRYLIC'!#REF!) -> #REF! | C34: =IF('GIA CONG ACRYLIC'!#REF!="","",'GIA CONG ACRYLIC'!#REF!) -> #REF! | D34: =IF('GIA CONG ACRYLIC'!#REF!="","",'GIA CONG ACRYLIC'!#REF!) -> #REF! | E34: =IF('GIA CONG ACRYLIC'!#REF!="","",'GIA CONG ACRYLIC'!#REF!) -> #REF! | F34: =IF('GIA CONG ACRYLIC'!#REF!="","",'GIA CONG ACRYLIC'!#REF!) -> #REF! | G34: =IF('GIA CONG ACRYLIC'!#REF!="","",'GIA CONG ACRYLIC'!#REF!) -> #REF! | H34: =IF('GIA CONG ACRYLIC'!#REF!="","",'GIA CONG ACRYLIC'!#REF!) -> #REF! | ... M34: =IF('GIA CONG ACRYLIC'!#REF!="","",'GIA CONG ACRYLIC'!#REF!) -> #REF! | N34: ='GIA CONG ACRYLIC'!$H$7 -> L3287 | O34: =IF('GIA CONG ACRYLIC'!#REF!+'GIA CONG ACRYLIC'!#REF!="","",'GIA CONG ACRYLIC'!#REF!+'GIA CONG ACRYLIC'!#REF!) -> #REF! | P34: =IF('LENH GIA CONG TAM'!H66="","",'LENH GIA CONG TAM'!H66) | Q34: =IF('LENH GIA CONG TAM'!I66="","",'LENH GIA CONG TAM'!I66) | R34: ='GIA CONG ACRYLIC'!$M$6 -> 46196.643 | S34: ='GIA CONG ACRYLIC'!$M$7 -> 2 | T34: ='GIA CONG ACRYLIC'!$M$8 -> 46198.643
A35: =IF('GIA CONG ACRYLIC'!A66="","",'GIA CONG ACRYLIC'!A66) | B35: =IF('GIA CONG ACRYLIC'!B66="","",'GIA CONG ACRYLIC'!B66) | C35: =IF('GIA CONG ACRYLIC'!C66="","",'GIA CONG ACRYLIC'!C66) | D35: =IF('GIA CONG ACRYLIC'!D66="","",'GIA CONG ACRYLIC'!D66) | E35: =IF('GIA CONG ACRYLIC'!E66="","",'GIA CONG ACRYLIC'!E66) | F35: =IF('GIA CONG ACRYLIC'!F66="","",'GIA CONG ACRYLIC'!F66) | G35: =IF('GIA CONG ACRYLIC'!G66="","",'GIA CONG ACRYLIC'!G66) | H35: =IF('GIA CONG ACRYLIC'!H66="","",'GIA CONG ACRYLIC'!H66) | ... M35: =IF('GIA CONG ACRYLIC'!M66="","",'GIA CONG ACRYLIC'!M66) | N35: ='GIA CONG ACRYLIC'!$H$7 -> L3287 | O35: =IF('GIA CONG ACRYLIC'!I66+'GIA CONG ACRYLIC'!J66="","",'GIA CONG ACRYLIC'!I66+'GIA CONG ACRYLIC'!J66) -> 0 | P35: =IF('LENH GIA CONG TAM'!H67="","",'LENH GIA CONG TAM'!H67) | Q35: =IF('LENH GIA CONG TAM'!I67="","",'LENH GIA CONG TAM'!I67) | R35: ='GIA CONG ACRYLIC'!$M$6 -> 46196.643 | S35: ='GIA CONG ACRYLIC'!$M$7 -> 2 | T35: ='GIA CONG ACRYLIC'!$M$8 -> 46198.643
A36: =IF('GIA CONG ACRYLIC'!A69="","",'GIA CONG ACRYLIC'!A69) -> Lưu ý: | B36: =IF('GIA CONG ACRYLIC'!B69="","",'GIA CONG ACRYLIC'!B69) | C36: =IF('GIA CONG ACRYLIC'!C69="","",'GIA CONG ACRYLIC'!C69) | D36: =IF('GIA CONG ACRYLIC'!D69="","",'GIA CONG ACRYLIC'!D69) | E36: =IF('GIA CONG ACRYLIC'!E69="","",'GIA CONG ACRYLIC'!E69) | F36: =IF('GIA CONG ACRYLIC'!F69="","",'GIA CONG ACRYLIC'!F69) | G36: =IF('GIA CONG ACRYLIC'!G69="","",'GIA CONG ACRYLIC'!G69) | H36: =IF('GIA CONG ACRYLIC'!H69="","",'GIA CONG ACRYLIC'!H69) | ... M36: =IF('GIA CONG ACRYLIC'!M69="","",'GIA CONG ACRYLIC'!M69) | N36: ='GIA CONG ACRYLIC'!$H$7 -> L3287 | O36: =IF('GIA CONG ACRYLIC'!I69+'GIA CONG ACRYLIC'!J69="","",'GIA CONG ACRYLIC'!I69+'GIA CONG ACRYLIC'!J69) -> 0 | P36: =IF('LENH GIA CONG TAM'!H24="","",'LENH GIA CONG TAM'!H24) -> 1.781 | Q36: =IF('LENH GIA CONG TAM'!I24="","",'LENH GIA CONG TAM'!I24) -> 0.315 | R36: ='GIA CONG ACRYLIC'!$M$6 -> 46196.643 | S36: ='GIA CONG ACRYLIC'!$M$7 -> 2 | T36: ='GIA CONG ACRYLIC'!$M$8 -> 46198.643
A37: =IF('GIA CONG ACRYLIC'!A70="","",'GIA CONG ACRYLIC'!A70) | B37: =IF('GIA CONG ACRYLIC'!B70="","",'GIA CONG ACRYLIC'!B70) | C37: =IF('GIA CONG ACRYLIC'!C70="","",'GIA CONG ACRYLIC'!C70) -> + Khách hàng phải kiểm tra và xác nhận đã nhận đầy đủ số lượng, tình trạng bên ngoài của hàng như hàng không bị xước hoặc hư hỏng. | D37: =IF('GIA CONG ACRYLIC'!D70="","",'GIA CONG ACRYLIC'!D70) | E37: =IF('GIA CONG ACRYLIC'!E70="","",'GIA CONG ACRYLIC'!E70) | F37: =IF('GIA CONG ACRYLIC'!F70="","",'GIA CONG ACRYLIC'!F70) | G37: =IF('GIA CONG ACRYLIC'!G70="","",'GIA CONG ACRYLIC'!G70) | H37: =IF('GIA CONG ACRYLIC'!H70="","",'GIA CONG ACRYLIC'!H70) | ... M37: =IF('GIA CONG ACRYLIC'!M70="","",'GIA CONG ACRYLIC'!M70) | N37: ='GIA CONG ACRYLIC'!$H$7 -> L3287 | O37: =IF('GIA CONG ACRYLIC'!I70+'GIA CONG ACRYLIC'!J70="","",'GIA CONG ACRYLIC'!I70+'GIA CONG ACRYLIC'!J70) -> 0 | P37: =IF('LENH GIA CONG TAM'!H25="","",'LENH GIA CONG TAM'!H25) -> 3.184 | Q37: =IF('LENH GIA CONG TAM'!I25="","",'LENH GIA CONG TAM'!I25) -> 0 | R37: ='GIA CONG ACRYLIC'!$M$6 -> 46196.643 | S37: ='GIA CONG ACRYLIC'!$M$7 -> 2 | T37: ='GIA CONG ACRYLIC'!$M$8 -> 46198.643
A38: =IF('GIA CONG ACRYLIC'!A71="","",'GIA CONG ACRYLIC'!A71) | B38: =IF('GIA CONG ACRYLIC'!B71="","",'GIA CONG ACRYLIC'!B71) | C38: =IF('GIA CONG ACRYLIC'!C71="","",'GIA CONG ACRYLIC'!C71) -> + Nếu khách hàng nhận hàng mà không kiểm tra hoặc bỏ qua bước kiểm tra và ký nhận thì bên cung cấp hàng không chịu trách nhiệm về việc hư hỏng hay thiếu sót hàng tính từ thời điểm giao xong hàng. | D38: =IF('GIA CONG ACRYLIC'!D71="","",'GIA CONG ACRYLIC'!D71) | E38: =IF('GIA CONG ACRYLIC'!E71="","",'GIA CONG ACRYLIC'!E71) | F38: =IF('GIA CONG ACRYLIC'!F71="","",'GIA CONG ACRYLIC'!F71) | G38: =IF('GIA CONG ACRYLIC'!G71="","",'GIA CONG ACRYLIC'!G71) | H38: =IF('GIA CONG ACRYLIC'!H71="","",'GIA CONG ACRYLIC'!H71) | ... M38: =IF('GIA CONG ACRYLIC'!M71="","",'GIA CONG ACRYLIC'!M71) | N38: ='GIA CONG ACRYLIC'!$H$7 -> L3287 | O38: =IF('GIA CONG ACRYLIC'!I71+'GIA CONG ACRYLIC'!J71="","",'GIA CONG ACRYLIC'!I71+'GIA CONG ACRYLIC'!J71) -> 0 | P38: =IF('LENH GIA CONG TAM'!H26="","",'LENH GIA CONG TAM'!H26) -> 2.87 | Q38: =IF('LENH GIA CONG TAM'!I26="","",'LENH GIA CONG TAM'!I26) -> 0 | R38: ='GIA CONG ACRYLIC'!$M$6 -> 46196.643 | S38: ='GIA CONG ACRYLIC'!$M$7 -> 2 | T38: ='GIA CONG ACRYLIC'!$M$8 -> 46198.643
A39: =IF('GIA CONG ACRYLIC'!A72="","",'GIA CONG ACRYLIC'!A72) | B39: =IF('GIA CONG ACRYLIC'!B72="","",'GIA CONG ACRYLIC'!B72) | C39: =IF('GIA CONG ACRYLIC'!C72="","",'GIA CONG ACRYLIC'!C72) | D39: =IF('GIA CONG ACRYLIC'!D72="","",'GIA CONG ACRYLIC'!D72) | E39: =IF('GIA CONG ACRYLIC'!E72="","",'GIA CONG ACRYLIC'!E72) | F39: =IF('GIA CONG ACRYLIC'!F72="","",'GIA CONG ACRYLIC'!F72) | G39: =IF('GIA CONG ACRYLIC'!G72="","",'GIA CONG ACRYLIC'!G72) | H39: =IF('GIA CONG ACRYLIC'!H72="","",'GIA CONG ACRYLIC'!H72) | ... M39: =IF('GIA CONG ACRYLIC'!M72="","",'GIA CONG ACRYLIC'!M72) | N39: ='GIA CONG ACRYLIC'!$H$7 -> L3287 | O39: =IF('GIA CONG ACRYLIC'!I72+'GIA CONG ACRYLIC'!J72="","",'GIA CONG ACRYLIC'!I72+'GIA CONG ACRYLIC'!J72) -> 0 | P39: =IF('LENH GIA CONG TAM'!H27="","",'LENH GIA CONG TAM'!H27) -> 1.489 | Q39: =IF('LENH GIA CONG TAM'!I27="","",'LENH GIA CONG TAM'!I27) -> 0.781 | R39: ='GIA CONG ACRYLIC'!$M$6 -> 46196.643 | S39: ='GIA CONG ACRYLIC'!$M$7 -> 2 | T39: ='GIA CONG ACRYLIC'!$M$8 -> 46198.643
A40: =IF('GIA CONG ACRYLIC'!A73="","",'GIA CONG ACRYLIC'!A73) | B40: =IF('GIA CONG ACRYLIC'!B73="","",'GIA CONG ACRYLIC'!B73) | C40: =IF('GIA CONG ACRYLIC'!C73="","",'GIA CONG ACRYLIC'!C73) -> XÁC NHẬN BÊN MUA HÀNG | D40: =IF('GIA CONG ACRYLIC'!D73="","",'GIA CONG ACRYLIC'!D73) | E40: =IF('GIA CONG ACRYLIC'!E73="","",'GIA CONG ACRYLIC'!E73) | F40: =IF('GIA CONG ACRYLIC'!F73="","",'GIA CONG ACRYLIC'!F73) | G40: =IF('GIA CONG ACRYLIC'!G73="","",'GIA CONG ACRYLIC'!G73) -> NGƯỜI CHÀO GIÁ | H40: =IF('GIA CONG ACRYLIC'!H73="","",'GIA CONG ACRYLIC'!H73) | ... M40: =IF('GIA CONG ACRYLIC'!M73="","",'GIA CONG ACRYLIC'!M73) | N40: ='GIA CONG ACRYLIC'!$H$7 -> L3287 | O40: =IF('GIA CONG ACRYLIC'!I73+'GIA CONG ACRYLIC'!J73="","",'GIA CONG ACRYLIC'!I73+'GIA CONG ACRYLIC'!J73) -> 0 | P40: =IF('LENH GIA CONG TAM'!H28="","",'LENH GIA CONG TAM'!H28) -> 1.489 | Q40: =IF('LENH GIA CONG TAM'!I28="","",'LENH GIA CONG TAM'!I28) -> 0.781 | R40: ='GIA CONG ACRYLIC'!$M$6 -> 46196.643 | S40: ='GIA CONG ACRYLIC'!$M$7 -> 2 | T40: ='GIA CONG ACRYLIC'!$M$8 -> 46198.643
A41: =IF('GIA CONG ACRYLIC'!A74="","",'GIA CONG ACRYLIC'!A74) | B41: =IF('GIA CONG ACRYLIC'!B74="","",'GIA CONG ACRYLIC'!B74) -> Ngày………….đã nhận đủ số lượng và đã kiểm tra hàng không bị xước hoặc hư hỏng. | C41: =IF('GIA CONG ACRYLIC'!C74="","",'GIA CONG ACRYLIC'!C74) | D41: =IF('GIA CONG ACRYLIC'!D74="","",'GIA CONG ACRYLIC'!D74) | E41: =IF('GIA CONG ACRYLIC'!E74="","",'GIA CONG ACRYLIC'!E74) | F41: =IF('GIA CONG ACRYLIC'!F74="","",'GIA CONG ACRYLIC'!F74) | G41: =IF('GIA CONG ACRYLIC'!G74="","",'GIA CONG ACRYLIC'!G74) -> (Ký, ghi rõ họ tên) | H41: =IF('GIA CONG ACRYLIC'!H74="","",'GIA CONG ACRYLIC'!H74) | ... M41: =IF('GIA CONG ACRYLIC'!M74="","",'GIA CONG ACRYLIC'!M74) | N41: ='GIA CONG ACRYLIC'!$H$7 -> L3287 | O41: =IF('GIA CONG ACRYLIC'!I74+'GIA CONG ACRYLIC'!J74="","",'GIA CONG ACRYLIC'!I74+'GIA CONG ACRYLIC'!J74) -> 0 | P41: =IF('LENH GIA CONG TAM'!H29="","",'LENH GIA CONG TAM'!H29) -> 1.843 | Q41: =IF('LENH GIA CONG TAM'!I29="","",'LENH GIA CONG TAM'!I29) -> 0.377 | R41: ='GIA CONG ACRYLIC'!$M$6 -> 46196.643 | S41: ='GIA CONG ACRYLIC'!$M$7 -> 2 | T41: ='GIA CONG ACRYLIC'!$M$8 -> 46198.643
A42: =IF('GIA CONG ACRYLIC'!A75="","",'GIA CONG ACRYLIC'!A75) | B42: =IF('GIA CONG ACRYLIC'!B75="","",'GIA CONG ACRYLIC'!B75) | C42: =IF('GIA CONG ACRYLIC'!C75="","",'GIA CONG ACRYLIC'!C75) -> (Ký, ghi rõ họ tên) | D42: =IF('GIA CONG ACRYLIC'!D75="","",'GIA CONG ACRYLIC'!D75) | E42: =IF('GIA CONG ACRYLIC'!E75="","",'GIA CONG ACRYLIC'!E75) | F42: =IF('GIA CONG ACRYLIC'!F75="","",'GIA CONG ACRYLIC'!F75) | G42: =IF('GIA CONG ACRYLIC'!G75="","",'GIA CONG ACRYLIC'!G75) | H42: =IF('GIA CONG ACRYLIC'!H75="","",'GIA CONG ACRYLIC'!H75) | ... M42: =IF('GIA CONG ACRYLIC'!M75="","",'GIA CONG ACRYLIC'!M75) | N42: ='GIA CONG ACRYLIC'!$H$7 -> L3287 | O42: =IF('GIA CONG ACRYLIC'!I75+'GIA CONG ACRYLIC'!J75="","",'GIA CONG ACRYLIC'!I75+'GIA CONG ACRYLIC'!J75) -> 0 | P42: =IF('LENH GIA CONG TAM'!H30="","",'LENH GIA CONG TAM'!H30) -> 1.797 | Q42: =IF('LENH GIA CONG TAM'!I30="","",'LENH GIA CONG TAM'!I30) -> 0.331 | R42: ='GIA CONG ACRYLIC'!$M$6 -> 46196.643 | S42: ='GIA CONG ACRYLIC'!$M$7 -> 2 | T42: ='GIA CONG ACRYLIC'!$M$8 -> 46198.643
A43: =IF('GIA CONG ACRYLIC'!A76="","",'GIA CONG ACRYLIC'!A76) | B43: =IF('GIA CONG ACRYLIC'!B76="","",'GIA CONG ACRYLIC'!B76) | C43: =IF('GIA CONG ACRYLIC'!C76="","",'GIA CONG ACRYLIC'!C76) | D43: =IF('GIA CONG ACRYLIC'!D76="","",'GIA CONG ACRYLIC'!D76) | E43: =IF('GIA CONG ACRYLIC'!E76="","",'GIA CONG ACRYLIC'!E76) | F43: =IF('GIA CONG ACRYLIC'!F76="","",'GIA CONG ACRYLIC'!F76) | G43: =IF('GIA CONG ACRYLIC'!G76="","",'GIA CONG ACRYLIC'!G76) | H43: =IF('GIA CONG ACRYLIC'!H76="","",'GIA CONG ACRYLIC'!H76) | ... M43: =IF('GIA CONG ACRYLIC'!M76="","",'GIA CONG ACRYLIC'!M76) | N43: ='GIA CONG ACRYLIC'!$H$7 -> L3287 | O43: =IF('GIA CONG ACRYLIC'!I76+'GIA CONG ACRYLIC'!J76="","",'GIA CONG ACRYLIC'!I76+'GIA CONG ACRYLIC'!J76) -> 0 | P43: =IF('LENH GIA CONG TAM'!H31="","",'LENH GIA CONG TAM'!H31) -> 1.57 | Q43: =IF('LENH GIA CONG TAM'!I31="","",'LENH GIA CONG TAM'!I31) -> 0 | R43: ='GIA CONG ACRYLIC'!$M$6 -> 46196.643 | S43: ='GIA CONG ACRYLIC'!$M$7 -> 2 | T43: ='GIA CONG ACRYLIC'!$M$8 -> 46198.643
...

Sheet BAZIS
A1: Cắt | B1: Đơn hàng | C1: Sản phẩm | D1: STT | F1: Tên | G1: Vật liệu | H1: Dài | I1: Rộng | J1: Dày | K1: Chiều vân | L1: Số lượng | M1: Kí hiệu nẹp L1 | N1: Kí hiệu nẹp L2 | O1: Kí hiệu nẹp W1 | P1: Kí hiệu nẹp W2 | Q1: Dày nẹp L1 | R1: Dày nẹp L2 | S1: Dày nẹp W1 | T1: Dày nẹp W2 | U1: Ghi chú | V1: Bao trong-Dịch trái | W1: Bao trong-Dịch phải | X1: Bao trong-Dịch trên | Y1: Bao trong-Dịch dưới | Z1: Xoi-Dịch trái-1 | AA1: Xoi-Dịch phải-1 | AB1: Xoi-Dịch trên-1 | AC1: Xoi-Dịch dưới-1 | AD1: Xoi-Rộng-1 | AE1: Xoi-Sâu-1 | AF1: Xoi-Dịch trái-2 | AG1: Xoi-Dịch phải-2 | AH1: Xoi-Dịch trên-2 | AI1: Xoi-Dịch dưới-2 | AJ1: Xoi-Rộng-2 | AK1: Xoi-Sâu-2
A2: Cutting | B2: Order | C2: Product Name | D2: Order Number | F2: Detail Name | G2: Material | H2: Height | I2: Width | J2: Thickness | K2: Texture Orientation | L2: Quantity | M2: Edge Banding L1 | N2: Edge Banding L2 | O2: Edge Banding W1 | P2: Edge Banding W2 | Q2: L1 Thickness | R2: L2 Thickness | S2: W1 Thickness | T2: W2 Thickness | U2: Note | V2: Internal Cutting Left Offset | W2: Internal Cutting Right Offset | X2: Internal Cutting Top Offset | Y2: Internal Cutting Bottom Offset | Z2: Milling Left Offset 1 | AA2: Milling Right Offset 1 | AB2: Milling Top Offset 1 | AC2: Milling Bottom Offset 1 | AD2: Milling Width 1 | AE2: Milling Depth 1 | AF2: Milling Left Offset 2 | AG2: Milling Right Offset 2 | AH2: Milling Top Offset 2 | AI2: Milling Bottom Offset 2 | AJ2: Milling Width 2 | AK2: Milling Depth 2
F3: ghi chú | N3: Cạnh vát | P3: Cạnh vát | U3: Cạnh vát
A4: V | B4: ACRILYC | C4: Thế Khánh (Đơn 2) 3398 | D4: 3398.GV65.001 | E4: Mã đơn + mã hàng + 3 số TT | F4: Tủ trên | G4: MDF GV65-1MẶT (19MM) | H4: 792 | I4: 320 | J4: 19 | K4: 2 | L4: 1 | M4: T | N4: T | O4: T | P4: V | Q4: 1e-05 | R4: 1e-05 | S4: 1e-05 | T4: 1e-05 | U4: Vát 320
A5: V | B5: ACRILYC | C5: Thế Khánh (Đơn 2) 3398 | D5: 3398.GV65.002 | F5: Tủ trên | G5: MDF GV65-1MẶT (19MM) | H5: 792 | I5: 320 | J5: 19 | K5: 2 | L5: 1 | M5: T | N5: T | O5: T | P5: V | Q5: 1e-05 | R5: 1e-05 | S5: 1e-05 | T5: 1e-05 | U5: Vát 320
A6: V | B6: ACRILYC | C6: Thế Khánh (Đơn 2) 3398 | D6: 3398.GV65.003 | F6: Tủ trên | G6: MDF GV65-1MẶT (19MM) | H6: 792 | I6: 341 | J6: 19 | K6: 2 | L6: 1 | M6: T | N6: T | O6: T | P6: V | Q6: 1e-05 | R6: 1e-05 | S6: 1e-05 | T6: 1e-05 | U6: Vát 341
A7: V | B7: ACRILYC | C7: Thế Khánh (Đơn 2) 3398 | D7: 3398.GV65.004 | F7: Tủ trên | G7: MDF GV65-1MẶT (19MM) | H7: 792 | I7: 341 | J7: 19 | K7: 2 | L7: 1 | M7: T | N7: T | O7: T | P7: V | Q7: 1e-05 | R7: 1e-05 | S7: 1e-05 | T7: 1e-05 | U7: Vát 341
A8: V | B8: ACRILYC | C8: Thế Khánh (Đơn 2) 3398 | D8: 3398.GV65.005 | F8: Tủ trên | G8: MDF GV65-1MẶT (19MM) | H8: 792 | I8: 341 | J8: 19 | K8: 2 | L8: 1 | M8: T | N8: T | O8: T | P8: V | Q8: 1e-05 | R8: 1e-05 | S8: 1e-05 | T8: 1e-05 | U8: Vát 341
A9: V | B9: ACRILYC | C9: Thế Khánh (Đơn 2) 3398 | D9: 3398.GV65.006 | F9: Tủ trên | G9: MDF GV65-1MẶT (19MM) | H9: 792 | I9: 335 | J9: 19 | K9: 2 | L9: 1 | M9: T | N9: T | O9: T | P9: V | Q9: 1e-05 | R9: 1e-05 | S9: 1e-05 | T9: 1e-05 | U9: Vát 335
A10: V | B10: ACRILYC | C10: Thế Khánh (Đơn 2) 3398 | D10: 3398.GV65.007 | F10: Tủ trên | G10: MDF GV65-1MẶT (19MM) | H10: 792 | I10: 251 | J10: 19 | K10: 2 | L10: 1 | M10: T | N10: T | O10: T | P10: V | Q10: 1e-05 | R10: 1e-05 | S10: 1e-05 | T10: 1e-05 | U10: Vát 251
A11: V | B11: ACRILYC | C11: Thế Khánh (Đơn 2) 3398 | D11: 3398.GV65.008 | F11: Tủ trên | G11: MDF GV65-1MẶT (19MM) | H11: 792 | I11: 251 | J11: 19 | K11: 2 | L11: 1 | M11: T | N11: T | O11: T | P11: V | Q11: 1e-05 | R11: 1e-05 | S11: 1e-05 | T11: 1e-05 | U11: Vát 251
A12: V | B12: ACRILYC | C12: Thế Khánh (Đơn 2) 3398 | D12: 3398.GV65.009 | F12: Tủ trên | G12: MDF GV65-1MẶT (19MM) | H12: 704 | I12: 354 | J12: 19 | K12: 2 | L12: 1 | M12: T | N12: T | O12: T | P12: V | Q12: 1e-05 | R12: 1e-05 | S12: 1e-05 | T12: 1e-05 | U12: Vát 354
A13: V | B13: ACRILYC | C13: Thế Khánh (Đơn 2) 3398 | D13: 3398.GV65.010 | F13: Tủ trên | G13: MDF GV65-1MẶT (19MM) | H13: 704 | I13: 354 | J13: 19 | K13: 2 | L13: 1 | M13: T | N13: T | O13: T | P13: V | Q13: 1e-05 | R13: 1e-05 | S13: 1e-05 | T13: 1e-05 | U13: Vát 354
A14: V | B14: ACRILYC | C14: Thế Khánh (Đơn 2) 3398 | D14: 3398.GV65.011 | F14: Hồi | G14: MDF GV65-1MẶT (19MM) | H14: 866 | I14: 370 | J14: 19 | K14: 2 | L14: 1 | M14: T | N14: T | O14: T | P14: T | Q14: 1e-05 | R14: 1e-05 | S14: 1e-05 | T14: 1e-05
A15: V | B15: ACRILYC | C15: Thế Khánh (Đơn 2) 3398 | D15: 3398.GV65.012 | F15: Hồi | G15: MDF GV65-1MẶT (19MM) | H15: 790 | I15: 570 | J15: 19 | K15: 2 | L15: 1 | M15: T | N15: T | O15: T | P15: T | Q15: 1e-05 | R15: 1e-05 | S15: 1e-05 | T15: 1e-05
