Workbook

Sheet GIA CONG LAMINATE
I5: BÁO GIÁ KIÊM ĐƠN ĐẶT HÀNG
I6: Ngày 10 tháng 03 năm 2026 | Q6: Ngày giờ chốt đơn: | R6: 46091.448
I7: Số phiếu: | Q7: Số ngày phải giao từ lúc chốt đơn: | R7: 2
D8: Khách hàng: KH0000 - Tên Khách hàng | Q8: Ngày giờ phải giao hàng: | R8: =R6+R7 -> 46093.448
D9: Địa chỉ:
D10: Công ty TNHH Gỗ GERVIN xin cảm ơn quý khách hàng đã tin dùng sản phẩm của chúng tôi và xin được báo giá như sau:
A11: Chi tiết | B11: Stt | C11: Mã hàng | D11: Tên hàng hóa, dịch vụ | E11: Kích thước (mm) | G11: Số lượng | H11: Cạnh vát | I11: Dán cạnh | M11: Số mét dán thẳng | N11: Số mét dán vát | O11: Số mét dán bản rộng 25-35mm | P11: Số mét dán ván chiều rộng 40-59mm | Q11: Số mét dán bản rộng 17-39mm | R11: Ghi chú
E12: Cao (chiều vân gỗ) | F12: Rộng | I12: Cao | J12: Cao | K12: Rộng | L12: Rộng | S12: Chiều vân
A13: CT | B13: A | D13: VẬT TƯ | G13: =SUM(G15:G68) -> 0 | M13: =SUM(M15:M68) -> 0 | N13: =SUM(N15:N68) -> 0 | O13: =SUM(O15:O68) -> 0 | P13: =SUM(P15:P68) -> 0 | Q13: =SUM(Q15:Q68) -> 0 | S13: Vát
A14: CT | B14: I | D14: Cốt MDF chống ẩm 17mm (Gervin), 2 mặt phủ Laminate AS-13005 CN74 màu đơn sắc (khách mang đến) = 2 tấm
A15: CT | B15: 1 | H15: =$S$13&S15 -> Vát 0 | M15: =(IF(I15="T", E15,0)+IF(J15="T", E15,0)+IF(K15="T", F15,0)+IF(L15="T", F15,0))/1000*G15 -> 0 | N15: =(IF(I15="V", E15,0)+IF(J15="V", E15,0)+IF(K15="V", F15,0)+IF(L15="V", F15,0))/1000*G15 -> 0 | O15: =(IF(I15="T42", E15,0)+IF(J15="T42", E15,0)+IF(K15="T42", F15,0)+IF(L15="T42", F15,0))/1000*G15 -> 0 | P15: =IF(OR(AND(E15>=40,E15<=59),AND(F15>=40,F15<=59)),M15,0) -> 0 | Q15: =IF(OR(E15<=39,F15 <= 39), M15,0) -> 0 | S15: =F15 -> 0
A16: CT | B16: 2 | H16: =$S$13&S16 -> Vát 0 | M16: =(IF(I16="T", E16,0)+IF(J16="T", E16,0)+IF(K16="T", F16,0)+IF(L16="T", F16,0))/1000*G16 -> 0 | N16: =(IF(I16="V", E16,0)+IF(J16="V", E16,0)+IF(K16="V", F16,0)+IF(L16="V", F16,0))/1000*G16 -> 0 | O16: =(IF(I16="T42", E16,0)+IF(J16="T42", E16,0)+IF(K16="T42", F16,0)+IF(L16="T42", F16,0))/1000*G16 -> 0 | P16: =IF(OR(AND(E16>=40,E16<=59),AND(F16>=40,F16<=59)),M16,0) -> 0 | Q16: =IF(OR(E16<=39,F16 <= 39), M16,0) -> 0 | S16: =F16 -> 0
A17: CT | B17: 3 | H17: =$S$13&S17 -> Vát 0 | M17: =(IF(I17="T", E17,0)+IF(J17="T", E17,0)+IF(K17="T", F17,0)+IF(L17="T", F17,0))/1000*G17 -> 0 | N17: =(IF(I17="V", E17,0)+IF(J17="V", E17,0)+IF(K17="V", F17,0)+IF(L17="V", F17,0))/1000*G17 -> 0 | O17: =(IF(I17="T42", E17,0)+IF(J17="T42", E17,0)+IF(K17="T42", F17,0)+IF(L17="T42", F17,0))/1000*G17 -> 0 | P17: =IF(OR(AND(E17>=40,E17<=59),AND(F17>=40,F17<=59)),M17,0) -> 0 | Q17: =IF(OR(E17<=39,F17 <= 39), M17,0) -> 0 | S17: =F17 -> 0
A18: CT | B18: 4 | H18: =$S$13&S18 -> Vát 0 | M18: =(IF(I18="T", E18,0)+IF(J18="T", E18,0)+IF(K18="T", F18,0)+IF(L18="T", F18,0))/1000*G18 -> 0 | N18: =(IF(I18="V", E18,0)+IF(J18="V", E18,0)+IF(K18="V", F18,0)+IF(L18="V", F18,0))/1000*G18 -> 0 | O18: =(IF(I18="T42", E18,0)+IF(J18="T42", E18,0)+IF(K18="T42", F18,0)+IF(L18="T42", F18,0))/1000*G18 -> 0 | P18: =IF(OR(AND(E18>=40,E18<=59),AND(F18>=40,F18<=59)),M18,0) -> 0 | Q18: =IF(OR(E18<=39,F18 <= 39), M18,0) -> 0 | S18: =F18 -> 0
A19: CT | B19: 5 | H19: =$S$13&S19 -> Vát 0 | M19: =(IF(I19="T", E19,0)+IF(J19="T", E19,0)+IF(K19="T", F19,0)+IF(L19="T", F19,0))/1000*G19 -> 0 | N19: =(IF(I19="V", E19,0)+IF(J19="V", E19,0)+IF(K19="V", F19,0)+IF(L19="V", F19,0))/1000*G19 -> 0 | O19: =(IF(I19="T42", E19,0)+IF(J19="T42", E19,0)+IF(K19="T42", F19,0)+IF(L19="T42", F19,0))/1000*G19 -> 0 | P19: =IF(OR(AND(E19>=40,E19<=59),AND(F19>=40,F19<=59)),M19,0) -> 0 | Q19: =IF(OR(E19<=39,F19 <= 39), M19,0) -> 0 | S19: =F19 -> 0
A20: CT | B20: 6 | H20: =$S$13&S20 -> Vát 0 | M20: =(IF(I20="T", E20,0)+IF(J20="T", E20,0)+IF(K20="T", F20,0)+IF(L20="T", F20,0))/1000*G20 -> 0 | N20: =(IF(I20="V", E20,0)+IF(J20="V", E20,0)+IF(K20="V", F20,0)+IF(L20="V", F20,0))/1000*G20 -> 0 | O20: =(IF(I20="T42", E20,0)+IF(J20="T42", E20,0)+IF(K20="T42", F20,0)+IF(L20="T42", F20,0))/1000*G20 -> 0 | P20: =IF(OR(AND(E20>=40,E20<=59),AND(F20>=40,F20<=59)),M20,0) -> 0 | Q20: =IF(OR(E20<=39,F20 <= 39), M20,0) -> 0 | S20: =F20 -> 0
A21: CT | B21: 7 | H21: =$S$13&S21 -> Vát 0 | M21: =(IF(I21="T", E21,0)+IF(J21="T", E21,0)+IF(K21="T", F21,0)+IF(L21="T", F21,0))/1000*G21 -> 0 | N21: =(IF(I21="V", E21,0)+IF(J21="V", E21,0)+IF(K21="V", F21,0)+IF(L21="V", F21,0))/1000*G21 -> 0 | O21: =(IF(I21="T42", E21,0)+IF(J21="T42", E21,0)+IF(K21="T42", F21,0)+IF(L21="T42", F21,0))/1000*G21 -> 0 | P21: =IF(OR(AND(E21>=40,E21<=59),AND(F21>=40,F21<=59)),M21,0) -> 0 | Q21: =IF(OR(E21<=39,F21 <= 39), M21,0) -> 0 | S21: =F21 -> 0
A22: CT | B22: 8 | H22: =$S$13&S22 -> Vát 0 | M22: =(IF(I22="T", E22,0)+IF(J22="T", E22,0)+IF(K22="T", F22,0)+IF(L22="T", F22,0))/1000*G22 -> 0 | N22: =(IF(I22="V", E22,0)+IF(J22="V", E22,0)+IF(K22="V", F22,0)+IF(L22="V", F22,0))/1000*G22 -> 0 | O22: =(IF(I22="T42", E22,0)+IF(J22="T42", E22,0)+IF(K22="T42", F22,0)+IF(L22="T42", F22,0))/1000*G22 -> 0 | P22: =IF(OR(AND(E22>=40,E22<=59),AND(F22>=40,F22<=59)),M22,0) -> 0 | Q22: =IF(OR(E22<=39,F22 <= 39), M22,0) -> 0 | S22: =F22 -> 0
A23: CT | B23: 9 | H23: =$S$13&S23 -> Vát 0 | M23: =(IF(I23="T", E23,0)+IF(J23="T", E23,0)+IF(K23="T", F23,0)+IF(L23="T", F23,0))/1000*G23 -> 0 | N23: =(IF(I23="V", E23,0)+IF(J23="V", E23,0)+IF(K23="V", F23,0)+IF(L23="V", F23,0))/1000*G23 -> 0 | O23: =(IF(I23="T42", E23,0)+IF(J23="T42", E23,0)+IF(K23="T42", F23,0)+IF(L23="T42", F23,0))/1000*G23 -> 0 | P23: =IF(OR(AND(E23>=40,E23<=59),AND(F23>=40,F23<=59)),M23,0) -> 0 | Q23: =IF(OR(E23<=39,F23 <= 39), M23,0) -> 0 | S23: =F23 -> 0
A24: CT | B24: 10 | H24: =$S$13&S24 -> Vát 0 | M24: =(IF(I24="T", E24,0)+IF(J24="T", E24,0)+IF(K24="T", F24,0)+IF(L24="T", F24,0))/1000*G24 -> 0 | N24: =(IF(I24="V", E24,0)+IF(J24="V", E24,0)+IF(K24="V", F24,0)+IF(L24="V", F24,0))/1000*G24 -> 0 | O24: =(IF(I24="T42", E24,0)+IF(J24="T42", E24,0)+IF(K24="T42", F24,0)+IF(L24="T42", F24,0))/1000*G24 -> 0 | P24: =IF(OR(AND(E24>=40,E24<=59),AND(F24>=40,F24<=59)),M24,0) -> 0 | Q24: =IF(OR(E24<=39,F24 <= 39), M24,0) -> 0 | S24: =F24 -> 0
A25: CT | B25: 11 | H25: =$S$13&S25 -> Vát 0 | M25: =(IF(I25="T", E25,0)+IF(J25="T", E25,0)+IF(K25="T", F25,0)+IF(L25="T", F25,0))/1000*G25 -> 0 | N25: =(IF(I25="V", E25,0)+IF(J25="V", E25,0)+IF(K25="V", F25,0)+IF(L25="V", F25,0))/1000*G25 -> 0 | O25: =(IF(I25="T42", E25,0)+IF(J25="T42", E25,0)+IF(K25="T42", F25,0)+IF(L25="T42", F25,0))/1000*G25 -> 0 | P25: =IF(OR(AND(E25>=40,E25<=59),AND(F25>=40,F25<=59)),M25,0) -> 0 | Q25: =IF(OR(E25<=39,F25 <= 39), M25,0) -> 0 | S25: =F25 -> 0
A26: CT | B26: 12 | H26: =$S$13&S26 -> Vát 0 | M26: =(IF(I26="T", E26,0)+IF(J26="T", E26,0)+IF(K26="T", F26,0)+IF(L26="T", F26,0))/1000*G26 -> 0 | N26: =(IF(I26="V", E26,0)+IF(J26="V", E26,0)+IF(K26="V", F26,0)+IF(L26="V", F26,0))/1000*G26 -> 0 | O26: =(IF(I26="T42", E26,0)+IF(J26="T42", E26,0)+IF(K26="T42", F26,0)+IF(L26="T42", F26,0))/1000*G26 -> 0 | P26: =IF(OR(AND(E26>=40,E26<=59),AND(F26>=40,F26<=59)),M26,0) -> 0 | Q26: =IF(OR(E26<=39,F26 <= 39), M26,0) -> 0 | S26: =F26 -> 0
... A28: CT | B28: 14 | H28: =$S$13&S28 -> Vát 0 | M28: =(IF(I28="T", E28,0)+IF(J28="T", E28,0)+IF(K28="T", F28,0)+IF(L28="T", F28,0))/1000*G28 -> 0 | N28: =(IF(I28="V", E28,0)+IF(J28="V", E28,0)+IF(K28="V", F28,0)+IF(L28="V", F28,0))/1000*G28 -> 0 | O28: =(IF(I28="T42", E28,0)+IF(J28="T42", E28,0)+IF(K28="T42", F28,0)+IF(L28="T42", F28,0))/1000*G28 -> 0 | P28: =IF(OR(AND(E28>=40,E28<=59),AND(F28>=40,F28<=59)),M28,0) -> 0 | Q28: =IF(OR(E28<=39,F28 <= 39), M28,0) -> 0 | S28: =F28 -> 0
A29: CT | B29: II | D29: Cốt MDF chống ẩm 17mm (Gervin), 2 mặt phủ Laminate AS - 14029 CS98 màu vân gỗ (khách mang đến) = 3 tấm
A30: CT | B30: 1 | H30: =$S$13&S30 -> Vát 0 | M30: =(IF(I30="T", E30,0)+IF(J30="T", E30,0)+IF(K30="T", F30,0)+IF(L30="T", F30,0))/1000*G30 -> 0 | N30: =(IF(I30="V", E30,0)+IF(J30="V", E30,0)+IF(K30="V", F30,0)+IF(L30="V", F30,0))/1000*G30 -> 0 | O30: =(IF(I30="T42", E30,0)+IF(J30="T42", E30,0)+IF(K30="T42", F30,0)+IF(L30="T42", F30,0))/1000*G30 -> 0 | P30: =IF(OR(AND(E30>=40,E30<=59),AND(F30>=40,F30<=59)),M30,0) -> 0 | Q30: =IF(OR(E30<=39,F30 <= 39), M30,0) -> 0 | S30: =F30 -> 0
A31: CT | B31: 2 | H31: =$S$13&S31 -> Vát 0 | M31: =(IF(I31="T", E31,0)+IF(J31="T", E31,0)+IF(K31="T", F31,0)+IF(L31="T", F31,0))/1000*G31 -> 0 | N31: =(IF(I31="V", E31,0)+IF(J31="V", E31,0)+IF(K31="V", F31,0)+IF(L31="V", F31,0))/1000*G31 -> 0 | O31: =(IF(I31="T42", E31,0)+IF(J31="T42", E31,0)+IF(K31="T42", F31,0)+IF(L31="T42", F31,0))/1000*G31 -> 0 | P31: =IF(OR(AND(E31>=40,E31<=59),AND(F31>=40,F31<=59)),M31,0) -> 0 | Q31: =IF(OR(E31<=39,F31 <= 39), M31,0) -> 0 | S31: =F31 -> 0
A32: CT | B32: 3 | H32: =$S$13&S32 -> Vát 0 | M32: =(IF(I32="T", E32,0)+IF(J32="T", E32,0)+IF(K32="T", F32,0)+IF(L32="T", F32,0))/1000*G32 -> 0 | N32: =(IF(I32="V", E32,0)+IF(J32="V", E32,0)+IF(K32="V", F32,0)+IF(L32="V", F32,0))/1000*G32 -> 0 | O32: =(IF(I32="T42", E32,0)+IF(J32="T42", E32,0)+IF(K32="T42", F32,0)+IF(L32="T42", F32,0))/1000*G32 -> 0 | P32: =IF(OR(AND(E32>=40,E32<=59),AND(F32>=40,F32<=59)),M32,0) -> 0 | Q32: =IF(OR(E32<=39,F32 <= 39), M32,0) -> 0 | S32: =F32 -> 0
A33: CT | B33: 4 | H33: =$S$13&S33 -> Vát 0 | M33: =(IF(I33="T", E33,0)+IF(J33="T", E33,0)+IF(K33="T", F33,0)+IF(L33="T", F33,0))/1000*G33 -> 0 | N33: =(IF(I33="V", E33,0)+IF(J33="V", E33,0)+IF(K33="V", F33,0)+IF(L33="V", F33,0))/1000*G33 -> 0 | O33: =(IF(I33="T42", E33,0)+IF(J33="T42", E33,0)+IF(K33="T42", F33,0)+IF(L33="T42", F33,0))/1000*G33 -> 0 | P33: =IF(OR(AND(E33>=40,E33<=59),AND(F33>=40,F33<=59)),M33,0) -> 0 | Q33: =IF(OR(E33<=39,F33 <= 39), M33,0) -> 0 | S33: =F33 -> 0
A34: CT | B34: 5 | H34: =$S$13&S34 -> Vát 0 | M34: =(IF(I34="T", E34,0)+IF(J34="T", E34,0)+IF(K34="T", F34,0)+IF(L34="T", F34,0))/1000*G34 -> 0 | N34: =(IF(I34="V", E34,0)+IF(J34="V", E34,0)+IF(K34="V", F34,0)+IF(L34="V", F34,0))/1000*G34 -> 0 | O34: =(IF(I34="T42", E34,0)+IF(J34="T42", E34,0)+IF(K34="T42", F34,0)+IF(L34="T42", F34,0))/1000*G34 -> 0 | P34: =IF(OR(AND(E34>=40,E34<=59),AND(F34>=40,F34<=59)),M34,0) -> 0 | Q34: =IF(OR(E34<=39,F34 <= 39), M34,0) -> 0 | S34: =F34 -> 0
A35: CT | B35: 6 | H35: =$S$13&S35 -> Vát 0 | M35: =(IF(I35="T", E35,0)+IF(J35="T", E35,0)+IF(K35="T", F35,0)+IF(L35="T", F35,0))/1000*G35 -> 0 | N35: =(IF(I35="V", E35,0)+IF(J35="V", E35,0)+IF(K35="V", F35,0)+IF(L35="V", F35,0))/1000*G35 -> 0 | O35: =(IF(I35="T42", E35,0)+IF(J35="T42", E35,0)+IF(K35="T42", F35,0)+IF(L35="T42", F35,0))/1000*G35 -> 0 | P35: =IF(OR(AND(E35>=40,E35<=59),AND(F35>=40,F35<=59)),M35,0) -> 0 | Q35: =IF(OR(E35<=39,F35 <= 39), M35,0) -> 0 | S35: =F35 -> 0
A36: CT | B36: 7 | H36: =$S$13&S36 -> Vát 0 | M36: =(IF(I36="T", E36,0)+IF(J36="T", E36,0)+IF(K36="T", F36,0)+IF(L36="T", F36,0))/1000*G36 -> 0 | N36: =(IF(I36="V", E36,0)+IF(J36="V", E36,0)+IF(K36="V", F36,0)+IF(L36="V", F36,0))/1000*G36 -> 0 | O36: =(IF(I36="T42", E36,0)+IF(J36="T42", E36,0)+IF(K36="T42", F36,0)+IF(L36="T42", F36,0))/1000*G36 -> 0 | P36: =IF(OR(AND(E36>=40,E36<=59),AND(F36>=40,F36<=59)),M36,0) -> 0 | Q36: =IF(OR(E36<=39,F36 <= 39), M36,0) -> 0 | S36: =F36 -> 0
A37: CT | B37: 8 | H37: =$S$13&S37 -> Vát 0 | M37: =(IF(I37="T", E37,0)+IF(J37="T", E37,0)+IF(K37="T", F37,0)+IF(L37="T", F37,0))/1000*G37 -> 0 | N37: =(IF(I37="V", E37,0)+IF(J37="V", E37,0)+IF(K37="V", F37,0)+IF(L37="V", F37,0))/1000*G37 -> 0 | O37: =(IF(I37="T42", E37,0)+IF(J37="T42", E37,0)+IF(K37="T42", F37,0)+IF(L37="T42", F37,0))/1000*G37 -> 0 | P37: =IF(OR(AND(E37>=40,E37<=59),AND(F37>=40,F37<=59)),M37,0) -> 0 | Q37: =IF(OR(E37<=39,F37 <= 39), M37,0) -> 0 | S37: =F37 -> 0
A38: CT | B38: 9 | H38: =$S$13&S38 -> Vát 0 | M38: =(IF(I38="T", E38,0)+IF(J38="T", E38,0)+IF(K38="T", F38,0)+IF(L38="T", F38,0))/1000*G38 -> 0 | N38: =(IF(I38="V", E38,0)+IF(J38="V", E38,0)+IF(K38="V", F38,0)+IF(L38="V", F38,0))/1000*G38 -> 0 | O38: =(IF(I38="T42", E38,0)+IF(J38="T42", E38,0)+IF(K38="T42", F38,0)+IF(L38="T42", F38,0))/1000*G38 -> 0 | P38: =IF(OR(AND(E38>=40,E38<=59),AND(F38>=40,F38<=59)),M38,0) -> 0 | Q38: =IF(OR(E38<=39,F38 <= 39), M38,0) -> 0 | S38: =F38 -> 0
A39: CT | B39: 10 | H39: =$S$13&S39 -> Vát 0 | M39: =(IF(I39="T", E39,0)+IF(J39="T", E39,0)+IF(K39="T", F39,0)+IF(L39="T", F39,0))/1000*G39 -> 0 | N39: =(IF(I39="V", E39,0)+IF(J39="V", E39,0)+IF(K39="V", F39,0)+IF(L39="V", F39,0))/1000*G39 -> 0 | O39: =(IF(I39="T42", E39,0)+IF(J39="T42", E39,0)+IF(K39="T42", F39,0)+IF(L39="T42", F39,0))/1000*G39 -> 0 | P39: =IF(OR(AND(E39>=40,E39<=59),AND(F39>=40,F39<=59)),M39,0) -> 0 | Q39: =IF(OR(E39<=39,F39 <= 39), M39,0) -> 0 | S39: =F39 -> 0
A40: CT | B40: 11 | H40: =$S$13&S40 -> Vát 0 | M40: =(IF(I40="T", E40,0)+IF(J40="T", E40,0)+IF(K40="T", F40,0)+IF(L40="T", F40,0))/1000*G40 -> 0 | N40: =(IF(I40="V", E40,0)+IF(J40="V", E40,0)+IF(K40="V", F40,0)+IF(L40="V", F40,0))/1000*G40 -> 0 | O40: =(IF(I40="T42", E40,0)+IF(J40="T42", E40,0)+IF(K40="T42", F40,0)+IF(L40="T42", F40,0))/1000*G40 -> 0 | P40: =IF(OR(AND(E40>=40,E40<=59),AND(F40>=40,F40<=59)),M40,0) -> 0 | Q40: =IF(OR(E40<=39,F40 <= 39), M40,0) -> 0 | S40: =F40 -> 0
A41: CT | B41: 12 | H41: =$S$13&S41 -> Vát 0 | M41: =(IF(I41="T", E41,0)+IF(J41="T", E41,0)+IF(K41="T", F41,0)+IF(L41="T", F41,0))/1000*G41 -> 0 | N41: =(IF(I41="V", E41,0)+IF(J41="V", E41,0)+IF(K41="V", F41,0)+IF(L41="V", F41,0))/1000*G41 -> 0 | O41: =(IF(I41="T42", E41,0)+IF(J41="T42", E41,0)+IF(K41="T42", F41,0)+IF(L41="T42", F41,0))/1000*G41 -> 0 | P41: =IF(OR(AND(E41>=40,E41<=59),AND(F41>=40,F41<=59)),M41,0) -> 0 | Q41: =IF(OR(E41<=39,F41 <= 39), M41,0) -> 0 | S41: =F41 -> 0
... A68: CT | B68: 39 | H68: =$S$13&S68 -> Vát 0 | M68: =(IF(I68="T", E68,0)+IF(J68="T", E68,0)+IF(K68="T", F68,0)+IF(L68="T", F68,0))/1000*G68 -> 0 | N68: =(IF(I68="V", E68,0)+IF(J68="V", E68,0)+IF(K68="V", F68,0)+IF(L68="V", F68,0))/1000*G68 -> 0 | O68: =(IF(I68="T42", E68,0)+IF(J68="T42", E68,0)+IF(K68="T42", F68,0)+IF(L68="T42", F68,0))/1000*G68 -> 0 | P68: =IF(OR(AND(E68>=40,E68<=59),AND(F68>=40,F68<=59)),M68,0) -> 0 | Q68: =IF(OR(E68<=39,F68 <= 39), M68,0) -> 0 | S68: =F68 -> 0
A69: CT | B69: B | D69: Tính giá bán sản phẩm, dịch vụ: | I69: Đơn vị | L69: Số lượng | M69: Đơn giá | N69: Đơn giá chỉ | R69: THÀNH TIỀN
A70: GC | B70: 1 | D70: =D14 -> Cốt MDF chống ẩm 17mm (Gervin), 2 mặt phủ Laminate AS-13005 CN74 màu đơn sắc (khách mang đến) = 2 tấm | I70: tấm | R70: =L70*M70+L70*N70 -> 0
A71: GC | B71: 2 | D71: =D29 -> Cốt MDF chống ẩm 17mm (Gervin), 2 mặt phủ Laminate AS - 14029 CS98 màu vân gỗ (khách mang đến) = 3 tấm | I71: tấm | R71: =L71*M71+L71*N71 -> 0
...

Sheet LENH GIA CONG TAM
D5: LỆNH GIA CÔNG TẤM
D6: ='GIA CONG LAMINATE'!I6 -> Ngày 10 tháng 03 năm 2026
D7: ='GIA CONG LAMINATE'!I7 -> Số phiếu: | E7: ='GIA CONG LAMINATE'!J7 -> 0
B8: ='GIA CONG LAMINATE'!D8 -> Khách hàng: KH0000 - Tên Khách hàng
B9: ='GIA CONG LAMINATE'!D9 -> Địa chỉ:
B10: Đề nghị BP Kỹ thuật gia công các sản phẩm dưới đây:
A11: ='GIA CONG LAMINATE'!B69 -> B | B11: ='GIA CONG LAMINATE'!D69 -> Tính giá bán sản phẩm, dịch vụ: | C11: ='GIA CONG LAMINATE'!I69 -> Đơn vị | F11: ='GIA CONG LAMINATE'!L69 -> Số lượng | J11: Ghi chú
A12: ='GIA CONG LAMINATE'!B70 -> 1 | B12: ='GIA CONG LAMINATE'!D70 -> Cốt MDF chống ẩm 17mm (Gervin), 2 mặt phủ Laminate AS-13005 CN74 màu đơn sắc (khách mang đến) = 2 tấm | C12: ='GIA CONG LAMINATE'!I70 -> tấm | F12: ='GIA CONG LAMINATE'!L70 -> 0
A13: ='GIA CONG LAMINATE'!B71 -> 2 | B13: ='GIA CONG LAMINATE'!D71 -> Cốt MDF chống ẩm 17mm (Gervin), 2 mặt phủ Laminate AS - 14029 CS98 màu vân gỗ (khách mang đến) = 3 tấm | C13: ='GIA CONG LAMINATE'!I71 -> tấm | F13: ='GIA CONG LAMINATE'!L71 -> 0
A14: ='GIA CONG LAMINATE'!B72 -> 3 | B14: ='GIA CONG LAMINATE'!D72 -> Công cắt tấm | C14: ='GIA CONG LAMINATE'!I72 -> tấm | F14: ='GIA CONG LAMINATE'!L72 -> 0
A15: ='GIA CONG LAMINATE'!B73 -> 4 | B15: ='GIA CONG LAMINATE'!D73 -> Dán cạnh thẳng laminate, melamine sử dụng keo chống thấm nước PUR: Áp dụng cho tấm ván có chiều rộng từ 60mm trở lên, độ dày ván 9-21mm, sử dụng máy dán Homag, Cộng hòa LB Đức. | C15: ='GIA CONG LAMINATE'!I73 -> m | F15: ='GIA CONG LAMINATE'!L73 -> 0
A16: ='GIA CONG LAMINATE'!B74 -> 5 | B16: ='GIA CONG LAMINATE'!D74 -> Dán cạnh thẳng laminate, melamine sử dụng keo chống thấm nước PUR: Áp dụng cho tấm ván có chiều rộng từ 40mm đến 59mm, độ dày ván 9-21mm nhân công, keo, băng dính dán cạnh thẳng laminate, melamine. (không bao gồm nẹp dán cạnh) sử dụng máy dán Homag, Cộng hòa LB Đức. | C16: ='GIA CONG LAMINATE'!I74 -> m | F16: ='GIA CONG LAMINATE'!L74 -> 0
A17: ='GIA CONG LAMINATE'!B75 -> 6 | B17: ='GIA CONG LAMINATE'!D75 -> Dán cạnh Vát sử dụng máy dán acrylic: Áp dụng cho tấm ván có chiều rộng từ 60mm trở lên, độ dày ván 9-21mm + Công hoàn thiện sản phẩm | C17: ='GIA CONG LAMINATE'!I75 -> m | F17: ='GIA CONG LAMINATE'!L75 -> 0
A18: ='GIA CONG LAMINATE'!B76 -> 7 | B18: ='GIA CONG LAMINATE'!D76 -> Nhân công và vật liệu đóng gói melamin, laminate | C18: ='GIA CONG LAMINATE'!I76 -> tấm | F18: ='GIA CONG LAMINATE'!L76 -> 0
A19: ='GIA CONG LAMINATE'!B77 -> 8 | B19: ='GIA CONG LAMINATE'!D77 -> Giao hàng tại Vinh | C19: ='GIA CONG LAMINATE'!I77 -> lần | F19: ='GIA CONG LAMINATE'!L77 -> 0
B21: Bên giao lệnh | E21: Kế toán | H21: Kỹ thuật | J21: Quản đốc/P.QĐ
B22: (Ký, ghi rõ họ tên) | E22: (Ký, ghi rõ họ tên) | H22: (Ký, ghi rõ họ tên) | J22: (Ký, ghi rõ họ tên)

Sheet DH
B1: STT | C1: MAHANGHOA | D1: TENHANGHOA | E1: CHIEUDAI | F1: CHIEURONG | G1: SOLUONG | H1: CANHVAT | L1: KHOILUONG | M1: DONGIA | N1: DONGIACHI | P1: SOTIENVND | Q1: CHIEUVAN | R1: SODONHANG | S1: GHICHUND | T1: NGAYCHOTDON | U1: SONGAY | V1: NGAYGIAO | W1: CANH | X1: THANHPHAO | Y1: DONGIAGIANTHANG | Z1: DONGIAGIANVAT | AA1: SOMETDANMOI | AB1: SOMETDANBR1759 | AC1: SOMETDANBR2535 | AD1: CONGDAN | AE1: SOVATTAYNAMAM | AF1: SOTAMCNC | AG1: SOMETDANTHANG | AH1: SOMETDANVAT
I5: BÁO GIÁ KIÊM ĐƠN ĐẶT HÀNG
I6: Ngày 10 tháng 07 năm 2024
I7: Số phiếu: | J7: 2504
D8: Khách hàng: Orient 37 Gia công
D9: Địa chỉ: Đường Lê Ngọc Hân, Nghi Đức, TP.Vinh, Nghệ An (SĐT: A Vinh: 0973362984) - Giao cùng đơn bảo hành
D10: Công ty TNHH Gỗ GERVIN xin cảm ơn quý khách hàng đã tin dùng sản phẩm của chúng tôi và xin được báo giá như sau:
A11: Chi tiết | B11: Stt | C11: Mã hàng | D11: Tên hàng hóa, dịch vụ | E11: Kích thước (mm) | G11: Số lượng | H11: Cạnh Vát | I11: Dán cạnh | M11: Số mét dán thẳng | N11: Số mét dán vát | O11: Số mét dán thẳng bản nhỏ từ 17- 39mm | P11: Ghi chú | Q11: Chiều vân | R11: Đơn hàng | S11: Ghi chú | T11: Ngày giờ chốt đơn: | U11: Số ngày phải giao từ lúc chốt đơn: | V11: Ngày giờ phải giao hàng:
E12: Cao (chiều vân gỗ) | F12: Rộng | I12: Cao | J12: Cao | K12: Rộng | L12: Rộng
A13: =IF('GIA CONG LAMINATE'!#REF!="CT","",'GIA CONG LAMINATE'!#REF!) -> #REF! | B13: =IF('GIA CONG LAMINATE'!#REF!="CT","",'GIA CONG LAMINATE'!#REF!) -> #REF! | C13: =IF('GIA CONG LAMINATE'!#REF!="CT","",'GIA CONG LAMINATE'!#REF!) -> #REF! | D13: =IF('GIA CONG LAMINATE'!#REF!="CT","",'GIA CONG LAMINATE'!#REF!) -> #REF! | E13: =IF('GIA CONG LAMINATE'!#REF!="CT","",'GIA CONG LAMINATE'!#REF!) -> #REF! | F13: =IF('GIA CONG LAMINATE'!#REF!="CT","",'GIA CONG LAMINATE'!#REF!) -> #REF! | G13: =IF('GIA CONG LAMINATE'!#REF!="CT","",'GIA CONG LAMINATE'!#REF!) -> #REF! | H13: =IF('GIA CONG LAMINATE'!#REF!="CT","",'GIA CONG LAMINATE'!#REF!) -> #REF! | ... Q13: =IF('GIA CONG LAMINATE'!#REF!="CT","",'GIA CONG LAMINATE'!#REF!) -> #REF! | R13: =IF('GIA CONG LAMINATE'!#REF!="CT","",'GIA CONG LAMINATE'!$J$7) -> #REF! | T13: ='GIA CONG LAMINATE'!$R$6 -> 46091.448 | U13: ='GIA CONG LAMINATE'!$R$7 -> 2 | V13: ='GIA CONG LAMINATE'!$R$8 -> 46093.448
A14: =IF('GIA CONG LAMINATE'!A70="CT","",'GIA CONG LAMINATE'!A70) -> GC | B14: =IF('GIA CONG LAMINATE'!A70="CT","",'GIA CONG LAMINATE'!B70) -> 1 | C14: =IF('GIA CONG LAMINATE'!A70="CT","",'GIA CONG LAMINATE'!C70) -> 0 | D14: =IF('GIA CONG LAMINATE'!A70="CT","",'GIA CONG LAMINATE'!D70) -> Cốt MDF chống ẩm 17mm (Gervin), 2 mặt phủ Laminate AS-13005 CN74 màu đơn sắc (khách mang đến) = 2 tấm | E14: =IF('GIA CONG LAMINATE'!A70="CT","",'GIA CONG LAMINATE'!E70) -> 0 | F14: =IF('GIA CONG LAMINATE'!A70="CT","",'GIA CONG LAMINATE'!F70) -> 0 | G14: =IF('GIA CONG LAMINATE'!A70="CT","",'GIA CONG LAMINATE'!L70) -> 0 | H14: =IF('GIA CONG LAMINATE'!A70="CT","",'GIA CONG LAMINATE'!H70) -> 0 | I14: =IF('GIA CONG LAMINATE'!A70="CT","",'GIA CONG LAMINATE'!I70) -> tấm | J14: =IF('GIA CONG LAMINATE'!A70="CT","",'GIA CONG LAMINATE'!J70) -> 0 | K14: =IF('GIA CONG LAMINATE'!A70="CT","",'GIA CONG LAMINATE'!K70) -> 0 | L14: =IF('GIA CONG LAMINATE'!A70="CT","",'GIA CONG LAMINATE'!L70) -> 0 | M14: =IF('GIA CONG LAMINATE'!A70="CT","",'GIA CONG LAMINATE'!M70) -> 0 | N14: =IF('GIA CONG LAMINATE'!A70="CT","",'GIA CONG LAMINATE'!N70) -> 0 | O14: =IF('GIA CONG LAMINATE'!A70="CT","",'GIA CONG LAMINATE'!O70) -> 0 | P14: =IF('GIA CONG LAMINATE'!A70="CT","",'GIA CONG LAMINATE'!R70) -> 0 | Q14: =IF('GIA CONG LAMINATE'!A70="CT","",'GIA CONG LAMINATE'!S70) -> 0 | R14: =IF('GIA CONG LAMINATE'!A70="CT","",'GIA CONG LAMINATE'!$J$7) -> 0 | T14: ='GIA CONG LAMINATE'!$R$6 -> 46091.448 | U14: ='GIA CONG LAMINATE'!$R$7 -> 2 | V14: ='GIA CONG LAMINATE'!$R$8 -> 46093.448
A15: =IF('GIA CONG LAMINATE'!A72="CT","",'GIA CONG LAMINATE'!A72) -> GC | B15: =IF('GIA CONG LAMINATE'!A72="CT","",'GIA CONG LAMINATE'!B72) -> 3 | C15: =IF('GIA CONG LAMINATE'!A72="CT","",'GIA CONG LAMINATE'!C72) -> 0 | D15: =IF('GIA CONG LAMINATE'!A72="CT","",'GIA CONG LAMINATE'!D72) -> Công cắt tấm | E15: =IF('GIA CONG LAMINATE'!A72="CT","",'GIA CONG LAMINATE'!E72) -> 0 | F15: =IF('GIA CONG LAMINATE'!A72="CT","",'GIA CONG LAMINATE'!F72) -> 0 | G15: =IF('GIA CONG LAMINATE'!A72="CT","",'GIA CONG LAMINATE'!L72) -> 0 | H15: =IF('GIA CONG LAMINATE'!A72="CT","",'GIA CONG LAMINATE'!H72) -> 0 | I15: =IF('GIA CONG LAMINATE'!A72="CT","",'GIA CONG LAMINATE'!I72) -> tấm | J15: =IF('GIA CONG LAMINATE'!A72="CT","",'GIA CONG LAMINATE'!J72) -> 0 | K15: =IF('GIA CONG LAMINATE'!A72="CT","",'GIA CONG LAMINATE'!K72) -> 0 | L15: =IF('GIA CONG LAMINATE'!A72="CT","",'GIA CONG LAMINATE'!L72) -> 0 | M15: =IF('GIA CONG LAMINATE'!A72="CT","",'GIA CONG LAMINATE'!M72) -> 0 | N15: =IF('GIA CONG LAMINATE'!A72="CT","",'GIA CONG LAMINATE'!N72) -> 0 | O15: =IF('GIA CONG LAMINATE'!A72="CT","",'GIA CONG LAMINATE'!O72) -> 0 | P15: =IF('GIA CONG LAMINATE'!A72="CT","",'GIA CONG LAMINATE'!R72) -> 0 | Q15: =IF('GIA CONG LAMINATE'!A72="CT","",'GIA CONG LAMINATE'!S72) -> 0 | R15: =IF('GIA CONG LAMINATE'!A72="CT","",'GIA CONG LAMINATE'!$J$7) -> 0 | T15: ='GIA CONG LAMINATE'!$R$6 -> 46091.448 | U15: ='GIA CONG LAMINATE'!$R$7 -> 2 | V15: ='GIA CONG LAMINATE'!$R$8 -> 46093.448
A16: =IF('GIA CONG LAMINATE'!A73="CT","",'GIA CONG LAMINATE'!A73) -> GC | B16: =IF('GIA CONG LAMINATE'!A73="CT","",'GIA CONG LAMINATE'!B73) -> 4 | C16: =IF('GIA CONG LAMINATE'!A73="CT","",'GIA CONG LAMINATE'!C73) -> 0 | D16: =IF('GIA CONG LAMINATE'!A73="CT","",'GIA CONG LAMINATE'!D73) -> Dán cạnh thẳng laminate, melamine sử dụng keo chống thấm nước PUR: Áp dụng cho tấm ván có chiều rộng từ 60mm trở lên, độ dày ván 9-21mm, sử dụng máy dán Homag, Cộng hòa LB Đức. | E16: =IF('GIA CONG LAMINATE'!A73="CT","",'GIA CONG LAMINATE'!E73) -> 0 | F16: =IF('GIA CONG LAMINATE'!A73="CT","",'GIA CONG LAMINATE'!F73) -> 0 | G16: =IF('GIA CONG LAMINATE'!A73="CT","",'GIA CONG LAMINATE'!L73) -> 0 | H16: =IF('GIA CONG LAMINATE'!A73="CT","",'GIA CONG LAMINATE'!H73) -> 0 | I16: =IF('GIA CONG LAMINATE'!A73="CT","",'GIA CONG LAMINATE'!I73) -> m | J16: =IF('GIA CONG LAMINATE'!A73="CT","",'GIA CONG LAMINATE'!J73) -> 0 | K16: =IF('GIA CONG LAMINATE'!A73="CT","",'GIA CONG LAMINATE'!K73) -> 0 | L16: =IF('GIA CONG LAMINATE'!A73="CT","",'GIA CONG LAMINATE'!L73) -> 0 | M16: =IF('GIA CONG LAMINATE'!A73="CT","",'GIA CONG LAMINATE'!M73) -> 0 | N16: =IF('GIA CONG LAMINATE'!A73="CT","",'GIA CONG LAMINATE'!N73) -> 0 | O16: =IF('GIA CONG LAMINATE'!A73="CT","",'GIA CONG LAMINATE'!O73) -> 0 | P16: =IF('GIA CONG LAMINATE'!A73="CT","",'GIA CONG LAMINATE'!R73) -> 0 | Q16: =IF('GIA CONG LAMINATE'!A73="CT","",'GIA CONG LAMINATE'!S73) -> 0 | R16: =IF('GIA CONG LAMINATE'!A73="CT","",'GIA CONG LAMINATE'!$J$7) -> 0 | T16: ='GIA CONG LAMINATE'!$R$6 -> 46091.448 | U16: ='GIA CONG LAMINATE'!$R$7 -> 2 | V16: ='GIA CONG LAMINATE'!$R$8 -> 46093.448
A17: =IF('GIA CONG LAMINATE'!#REF!="CT","",'GIA CONG LAMINATE'!#REF!) -> #REF! | B17: =IF('GIA CONG LAMINATE'!#REF!="CT","",'GIA CONG LAMINATE'!#REF!) -> #REF! | C17: =IF('GIA CONG LAMINATE'!#REF!="CT","",'GIA CONG LAMINATE'!#REF!) -> #REF! | D17: =IF('GIA CONG LAMINATE'!#REF!="CT","",'GIA CONG LAMINATE'!#REF!) -> #REF! | E17: =IF('GIA CONG LAMINATE'!#REF!="CT","",'GIA CONG LAMINATE'!#REF!) -> #REF! | F17: =IF('GIA CONG LAMINATE'!#REF!="CT","",'GIA CONG LAMINATE'!#REF!) -> #REF! | G17: =IF('GIA CONG LAMINATE'!#REF!="CT","",'GIA CONG LAMINATE'!#REF!) -> #REF! | H17: =IF('GIA CONG LAMINATE'!#REF!="CT","",'GIA CONG LAMINATE'!#REF!) -> #REF! | ... Q17: =IF('GIA CONG LAMINATE'!#REF!="CT","",'GIA CONG LAMINATE'!#REF!) -> #REF! | R17: =IF('GIA CONG LAMINATE'!#REF!="CT","",'GIA CONG LAMINATE'!$J$7) -> #REF! | T17: ='GIA CONG LAMINATE'!$R$6 -> 46091.448 | U17: ='GIA CONG LAMINATE'!$R$7 -> 2 | V17: ='GIA CONG LAMINATE'!$R$8 -> 46093.448
A18: =IF('GIA CONG LAMINATE'!#REF!="CT","",'GIA CONG LAMINATE'!#REF!) -> #REF! | B18: =IF('GIA CONG LAMINATE'!#REF!="CT","",'GIA CONG LAMINATE'!#REF!) -> #REF! | C18: =IF('GIA CONG LAMINATE'!#REF!="CT","",'GIA CONG LAMINATE'!#REF!) -> #REF! | D18: =IF('GIA CONG LAMINATE'!#REF!="CT","",'GIA CONG LAMINATE'!#REF!) -> #REF! | E18: =IF('GIA CONG LAMINATE'!#REF!="CT","",'GIA CONG LAMINATE'!#REF!) -> #REF! | F18: =IF('GIA CONG LAMINATE'!#REF!="CT","",'GIA CONG LAMINATE'!#REF!) -> #REF! | G18: =IF('GIA CONG LAMINATE'!#REF!="CT","",'GIA CONG LAMINATE'!#REF!) -> #REF! | H18: =IF('GIA CONG LAMINATE'!#REF!="CT","",'GIA CONG LAMINATE'!#REF!) -> #REF! | ... Q18: =IF('GIA CONG LAMINATE'!#REF!="CT","",'GIA CONG LAMINATE'!#REF!) -> #REF! | R18: =IF('GIA CONG LAMINATE'!#REF!="CT","",'GIA CONG LAMINATE'!$J$7) -> #REF! | T18: ='GIA CONG LAMINATE'!$R$6 -> 46091.448 | U18: ='GIA CONG LAMINATE'!$R$7 -> 2 | V18: ='GIA CONG LAMINATE'!$R$8 -> 46093.448
A19: =IF('GIA CONG LAMINATE'!A75="CT","",'GIA CONG LAMINATE'!A75) -> GC | B19: =IF('GIA CONG LAMINATE'!A75="CT","",'GIA CONG LAMINATE'!B75) -> 6 | C19: =IF('GIA CONG LAMINATE'!A75="CT","",'GIA CONG LAMINATE'!C75) -> 0 | D19: =IF('GIA CONG LAMINATE'!A75="CT","",'GIA CONG LAMINATE'!D75) -> Dán cạnh Vát sử dụng máy dán acrylic: Áp dụng cho tấm ván có chiều rộng từ 60mm trở lên, độ dày ván 9-21mm + Công hoàn thiện sản phẩm | E19: =IF('GIA CONG LAMINATE'!A75="CT","",'GIA CONG LAMINATE'!E75) -> 0 | F19: =IF('GIA CONG LAMINATE'!A75="CT","",'GIA CONG LAMINATE'!F75) -> 0 | G19: =IF('GIA CONG LAMINATE'!A75="CT","",'GIA CONG LAMINATE'!L75) -> 0 | H19: =IF('GIA CONG LAMINATE'!A75="CT","",'GIA CONG LAMINATE'!H75) -> 0 | I19: =IF('GIA CONG LAMINATE'!A75="CT","",'GIA CONG LAMINATE'!I75) -> m | J19: =IF('GIA CONG LAMINATE'!A75="CT","",'GIA CONG LAMINATE'!J75) -> 0 | K19: =IF('GIA CONG LAMINATE'!A75="CT","",'GIA CONG LAMINATE'!K75) -> 0 | L19: =IF('GIA CONG LAMINATE'!A75="CT","",'GIA CONG LAMINATE'!L75) -> 0 | M19: =IF('GIA CONG LAMINATE'!A75="CT","",'GIA CONG LAMINATE'!M75) -> 0 | N19: =IF('GIA CONG LAMINATE'!A75="CT","",'GIA CONG LAMINATE'!N75) -> 0 | O19: =IF('GIA CONG LAMINATE'!A75="CT","",'GIA CONG LAMINATE'!O75) -> 0 | P19: =IF('GIA CONG LAMINATE'!A75="CT","",'GIA CONG LAMINATE'!R75) -> 0 | Q19: =IF('GIA CONG LAMINATE'!A75="CT","",'GIA CONG LAMINATE'!S75) -> 0 | R19: =IF('GIA CONG LAMINATE'!A75="CT","",'GIA CONG LAMINATE'!$J$7) -> 0 | T19: ='GIA CONG LAMINATE'!$R$6 -> 46091.448 | U19: ='GIA CONG LAMINATE'!$R$7 -> 2 | V19: ='GIA CONG LAMINATE'!$R$8 -> 46093.448
A20: =IF('GIA CONG LAMINATE'!A76="CT","",'GIA CONG LAMINATE'!A76) -> GC | B20: =IF('GIA CONG LAMINATE'!A76="CT","",'GIA CONG LAMINATE'!B76) -> 7 | C20: =IF('GIA CONG LAMINATE'!A76="CT","",'GIA CONG LAMINATE'!C76) -> 0 | D20: =IF('GIA CONG LAMINATE'!A76="CT","",'GIA CONG LAMINATE'!D76) -> Nhân công và vật liệu đóng gói melamin, laminate | E20: =IF('GIA CONG LAMINATE'!A76="CT","",'GIA CONG LAMINATE'!E76) -> 0 | F20: =IF('GIA CONG LAMINATE'!A76="CT","",'GIA CONG LAMINATE'!F76) -> 0 | G20: =IF('GIA CONG LAMINATE'!A76="CT","",'GIA CONG LAMINATE'!L76) -> 0 | H20: =IF('GIA CONG LAMINATE'!A76="CT","",'GIA CONG LAMINATE'!H76) -> 0 | I20: =IF('GIA CONG LAMINATE'!A76="CT","",'GIA CONG LAMINATE'!I76) -> tấm | J20: =IF('GIA CONG LAMINATE'!A76="CT","",'GIA CONG LAMINATE'!J76) -> 0 | K20: =IF('GIA CONG LAMINATE'!A76="CT","",'GIA CONG LAMINATE'!K76) -> 0 | L20: =IF('GIA CONG LAMINATE'!A76="CT","",'GIA CONG LAMINATE'!L76) -> 0 | M20: =IF('GIA CONG LAMINATE'!A76="CT","",'GIA CONG LAMINATE'!M76) -> 0 | N20: =IF('GIA CONG LAMINATE'!A76="CT","",'GIA CONG LAMINATE'!N76) -> 0 | O20: =IF('GIA CONG LAMINATE'!A76="CT","",'GIA CONG LAMINATE'!O76) -> 0 | P20: =IF('GIA CONG LAMINATE'!A76="CT","",'GIA CONG LAMINATE'!R76) -> 0 | Q20: =IF('GIA CONG LAMINATE'!A76="CT","",'GIA CONG LAMINATE'!S76) -> 0 | R20: =IF('GIA CONG LAMINATE'!A76="CT","",'GIA CONG LAMINATE'!$J$7) -> 0 | T20: ='GIA CONG LAMINATE'!$R$6 -> 46091.448 | U20: ='GIA CONG LAMINATE'!$R$7 -> 2 | V20: ='GIA CONG LAMINATE'!$R$8 -> 46093.448
A21: =IF('GIA CONG LAMINATE'!A77="CT","",'GIA CONG LAMINATE'!A77) -> GC | B21: =IF('GIA CONG LAMINATE'!A77="CT","",'GIA CONG LAMINATE'!B77) -> 8 | C21: =IF('GIA CONG LAMINATE'!A77="CT","",'GIA CONG LAMINATE'!C77) -> 0 | D21: =IF('GIA CONG LAMINATE'!A77="CT","",'GIA CONG LAMINATE'!D77) -> Giao hàng tại Vinh | E21: =IF('GIA CONG LAMINATE'!A77="CT","",'GIA CONG LAMINATE'!E77) -> 0 | F21: =IF('GIA CONG LAMINATE'!A77="CT","",'GIA CONG LAMINATE'!F77) -> 0 | G21: =IF('GIA CONG LAMINATE'!A77="CT","",'GIA CONG LAMINATE'!L77) -> 0 | H21: =IF('GIA CONG LAMINATE'!A77="CT","",'GIA CONG LAMINATE'!H77) -> 0 | I21: =IF('GIA CONG LAMINATE'!A77="CT","",'GIA CONG LAMINATE'!I77) -> lần | J21: =IF('GIA CONG LAMINATE'!A77="CT","",'GIA CONG LAMINATE'!J77) -> 0 | K21: =IF('GIA CONG LAMINATE'!A77="CT","",'GIA CONG LAMINATE'!K77) -> 0 | L21: =IF('GIA CONG LAMINATE'!A77="CT","",'GIA CONG LAMINATE'!L77) -> 0 | M21: =IF('GIA CONG LAMINATE'!A77="CT","",'GIA CONG LAMINATE'!M77) -> 0 | N21: =IF('GIA CONG LAMINATE'!A77="CT","",'GIA CONG LAMINATE'!N77) -> 0 | O21: =IF('GIA CONG LAMINATE'!A77="CT","",'GIA CONG LAMINATE'!O77) -> 0 | P21: =IF('GIA CONG LAMINATE'!A77="CT","",'GIA CONG LAMINATE'!R77) -> 0 | Q21: =IF('GIA CONG LAMINATE'!A77="CT","",'GIA CONG LAMINATE'!S77) -> 0 | R21: =IF('GIA CONG LAMINATE'!A77="CT","",'GIA CONG LAMINATE'!$J$7) -> 0 | T21: ='GIA CONG LAMINATE'!$R$6 -> 46091.448 | U21: ='GIA CONG LAMINATE'!$R$7 -> 2 | V21: ='GIA CONG LAMINATE'!$R$8 -> 46093.448
A22: =IF('GIA CONG LAMINATE'!A78="CT","",'GIA CONG LAMINATE'!A78) -> 0 | B22: =IF('GIA CONG LAMINATE'!A78="CT","",'GIA CONG LAMINATE'!B78) -> 0 | C22: =IF('GIA CONG LAMINATE'!A78="CT","",'GIA CONG LAMINATE'!C78) -> 0 | D22: =IF('GIA CONG LAMINATE'!A78="CT","",'GIA CONG LAMINATE'!D78) -> 0 | E22: =IF('GIA CONG LAMINATE'!A78="CT","",'GIA CONG LAMINATE'!E78) -> 0 | F22: =IF('GIA CONG LAMINATE'!A78="CT","",'GIA CONG LAMINATE'!F78) -> 0 | G22: =IF('GIA CONG LAMINATE'!A78="CT","",'GIA CONG LAMINATE'!L78) -> 0 | H22: =IF('GIA CONG LAMINATE'!A78="CT","",'GIA CONG LAMINATE'!H78) -> 0 | I22: =IF('GIA CONG LAMINATE'!A78="CT","",'GIA CONG LAMINATE'!I78) -> 0 | J22: =IF('GIA CONG LAMINATE'!A78="CT","",'GIA CONG LAMINATE'!J78) -> 0 | K22: =IF('GIA CONG LAMINATE'!A78="CT","",'GIA CONG LAMINATE'!K78) -> 0 | L22: =IF('GIA CONG LAMINATE'!A78="CT","",'GIA CONG LAMINATE'!L78) -> 0 | M22: =IF('GIA CONG LAMINATE'!A78="CT","",'GIA CONG LAMINATE'!M78) -> 0 | N22: =IF('GIA CONG LAMINATE'!A78="CT","",'GIA CONG LAMINATE'!N78) -> 0 | O22: =IF('GIA CONG LAMINATE'!A78="CT","",'GIA CONG LAMINATE'!O78) -> 0 | P22: =IF('GIA CONG LAMINATE'!A78="CT","",'GIA CONG LAMINATE'!R78) -> 0 | Q22: =IF('GIA CONG LAMINATE'!A78="CT","",'GIA CONG LAMINATE'!S78) -> 0 | R22: =IF('GIA CONG LAMINATE'!A78="CT","",'GIA CONG LAMINATE'!$J$7) -> 0 | T22: ='GIA CONG LAMINATE'!$R$6 -> 46091.448 | U22: ='GIA CONG LAMINATE'!$R$7 -> 2 | V22: ='GIA CONG LAMINATE'!$R$8 -> 46093.448
A23: =IF('GIA CONG LAMINATE'!#REF!="CT","",'GIA CONG LAMINATE'!#REF!) -> #REF! | B23: =IF('GIA CONG LAMINATE'!#REF!="CT","",'GIA CONG LAMINATE'!#REF!) -> #REF! | C23: =IF('GIA CONG LAMINATE'!#REF!="CT","",'GIA CONG LAMINATE'!#REF!) -> #REF! | D23: =IF('GIA CONG LAMINATE'!#REF!="CT","",'GIA CONG LAMINATE'!#REF!) -> #REF! | E23: =IF('GIA CONG LAMINATE'!#REF!="CT","",'GIA CONG LAMINATE'!#REF!) -> #REF! | F23: =IF('GIA CONG LAMINATE'!#REF!="CT","",'GIA CONG LAMINATE'!#REF!) -> #REF! | G23: =IF('GIA CONG LAMINATE'!#REF!="CT","",'GIA CONG LAMINATE'!#REF!) -> #REF! | H23: =IF('GIA CONG LAMINATE'!#REF!="CT","",'GIA CONG LAMINATE'!#REF!) -> #REF! | ... Q23: =IF('GIA CONG LAMINATE'!#REF!="CT","",'GIA CONG LAMINATE'!#REF!) -> #REF! | R23: =IF('GIA CONG LAMINATE'!#REF!="CT","",'GIA CONG LAMINATE'!$J$7) -> #REF! | T23: ='GIA CONG LAMINATE'!$R$6 -> 46091.448 | U23: ='GIA CONG LAMINATE'!$R$7 -> 2 | V23: ='GIA CONG LAMINATE'!$R$8 -> 46093.448
A24: =IF('GIA CONG LAMINATE'!A79="CT","",'GIA CONG LAMINATE'!A79) -> 0 | B24: =IF('GIA CONG LAMINATE'!A79="CT","",'GIA CONG LAMINATE'!B79) -> 0 | C24: =IF('GIA CONG LAMINATE'!A79="CT","",'GIA CONG LAMINATE'!C79) -> 0 | D24: =IF('GIA CONG LAMINATE'!A79="CT","",'GIA CONG LAMINATE'!D79) -> 0 | E24: =IF('GIA CONG LAMINATE'!A79="CT","",'GIA CONG LAMINATE'!E79) -> 0 | F24: =IF('GIA CONG LAMINATE'!A79="CT","",'GIA CONG LAMINATE'!F79) -> 0 | G24: =IF('GIA CONG LAMINATE'!A79="CT","",'GIA CONG LAMINATE'!L79) -> 0 | H24: =IF('GIA CONG LAMINATE'!A79="CT","",'GIA CONG LAMINATE'!H79) -> 0 | I24: =IF('GIA CONG LAMINATE'!A79="CT","",'GIA CONG LAMINATE'!I79) -> 0 | J24: =IF('GIA CONG LAMINATE'!A79="CT","",'GIA CONG LAMINATE'!J79) -> 0 | K24: =IF('GIA CONG LAMINATE'!A79="CT","",'GIA CONG LAMINATE'!K79) -> 0 | L24: =IF('GIA CONG LAMINATE'!A79="CT","",'GIA CONG LAMINATE'!L79) -> 0 | M24: =IF('GIA CONG LAMINATE'!A79="CT","",'GIA CONG LAMINATE'!M79) -> 0 | N24: =IF('GIA CONG LAMINATE'!A79="CT","",'GIA CONG LAMINATE'!N79) -> 0 | O24: =IF('GIA CONG LAMINATE'!A79="CT","",'GIA CONG LAMINATE'!O79) -> 0 | P24: =IF('GIA CONG LAMINATE'!A79="CT","",'GIA CONG LAMINATE'!R79) -> 0 | Q24: =IF('GIA CONG LAMINATE'!A79="CT","",'GIA CONG LAMINATE'!S79) -> 0 | R24: =IF('GIA CONG LAMINATE'!A79="CT","",'GIA CONG LAMINATE'!$J$7) -> 0 | T24: ='GIA CONG LAMINATE'!$R$6 -> 46091.448 | U24: ='GIA CONG LAMINATE'!$R$7 -> 2 | V24: ='GIA CONG LAMINATE'!$R$8 -> 46093.448
A25: =IF('GIA CONG LAMINATE'!A80="CT","",'GIA CONG LAMINATE'!A80) -> 0 | B25: =IF('GIA CONG LAMINATE'!A80="CT","",'GIA CONG LAMINATE'!B80) -> 0 | C25: =IF('GIA CONG LAMINATE'!A80="CT","",'GIA CONG LAMINATE'!C80) -> 0 | D25: =IF('GIA CONG LAMINATE'!A80="CT","",'GIA CONG LAMINATE'!D80) -> 0 | E25: =IF('GIA CONG LAMINATE'!A80="CT","",'GIA CONG LAMINATE'!E80) -> 0 | F25: =IF('GIA CONG LAMINATE'!A80="CT","",'GIA CONG LAMINATE'!F80) -> 0 | G25: =IF('GIA CONG LAMINATE'!A80="CT","",'GIA CONG LAMINATE'!L80) -> 0 | H25: =IF('GIA CONG LAMINATE'!A80="CT","",'GIA CONG LAMINATE'!H80) -> 0 | I25: =IF('GIA CONG LAMINATE'!A80="CT","",'GIA CONG LAMINATE'!I80) -> 0 | J25: =IF('GIA CONG LAMINATE'!A80="CT","",'GIA CONG LAMINATE'!J80) -> 0 | K25: =IF('GIA CONG LAMINATE'!A80="CT","",'GIA CONG LAMINATE'!K80) -> 0 | L25: =IF('GIA CONG LAMINATE'!A80="CT","",'GIA CONG LAMINATE'!L80) -> 0 | M25: =IF('GIA CONG LAMINATE'!A80="CT","",'GIA CONG LAMINATE'!M80) -> 0 | N25: =IF('GIA CONG LAMINATE'!A80="CT","",'GIA CONG LAMINATE'!N80) -> 0 | O25: =IF('GIA CONG LAMINATE'!A80="CT","",'GIA CONG LAMINATE'!O80) -> 0 | P25: =IF('GIA CONG LAMINATE'!A80="CT","",'GIA CONG LAMINATE'!R80) -> 0 | Q25: =IF('GIA CONG LAMINATE'!A80="CT","",'GIA CONG LAMINATE'!S80) -> 0 | R25: =IF('GIA CONG LAMINATE'!A80="CT","",'GIA CONG LAMINATE'!$J$7) -> 0 | T25: ='GIA CONG LAMINATE'!$R$6 -> 46091.448 | U25: ='GIA CONG LAMINATE'!$R$7 -> 2 | V25: ='GIA CONG LAMINATE'!$R$8 -> 46093.448
A26: =IF('GIA CONG LAMINATE'!A81="CT","",'GIA CONG LAMINATE'!A81) -> 0 | B26: =IF('GIA CONG LAMINATE'!A81="CT","",'GIA CONG LAMINATE'!B81) -> Ghi chú: | C26: =IF('GIA CONG LAMINATE'!A81="CT","",'GIA CONG LAMINATE'!C81) -> 0 | D26: =IF('GIA CONG LAMINATE'!A81="CT","",'GIA CONG LAMINATE'!D81) -> 0 | E26: =IF('GIA CONG LAMINATE'!A81="CT","",'GIA CONG LAMINATE'!E81) -> 0 | F26: =IF('GIA CONG LAMINATE'!A81="CT","",'GIA CONG LAMINATE'!F81) -> 0 | G26: =IF('GIA CONG LAMINATE'!A81="CT","",'GIA CONG LAMINATE'!L81) -> 0 | H26: =IF('GIA CONG LAMINATE'!A81="CT","",'GIA CONG LAMINATE'!H81) -> 0 | I26: =IF('GIA CONG LAMINATE'!A81="CT","",'GIA CONG LAMINATE'!I81) -> 0 | J26: =IF('GIA CONG LAMINATE'!A81="CT","",'GIA CONG LAMINATE'!J81) -> 0 | K26: =IF('GIA CONG LAMINATE'!A81="CT","",'GIA CONG LAMINATE'!K81) -> 0 | L26: =IF('GIA CONG LAMINATE'!A81="CT","",'GIA CONG LAMINATE'!L81) -> 0 | M26: =IF('GIA CONG LAMINATE'!A81="CT","",'GIA CONG LAMINATE'!M81) -> 0 | N26: =IF('GIA CONG LAMINATE'!A81="CT","",'GIA CONG LAMINATE'!N81) -> 0 | O26: =IF('GIA CONG LAMINATE'!A81="CT","",'GIA CONG LAMINATE'!O81) -> 0 | P26: =IF('GIA CONG LAMINATE'!A81="CT","",'GIA CONG LAMINATE'!R81) -> 0 | Q26: =IF('GIA CONG LAMINATE'!A81="CT","",'GIA CONG LAMINATE'!S81) -> 0 | R26: =IF('GIA CONG LAMINATE'!A81="CT","",'GIA CONG LAMINATE'!$J$7) -> 0 | T26: ='GIA CONG LAMINATE'!$R$6 -> 46091.448 | U26: ='GIA CONG LAMINATE'!$R$7 -> 2 | V26: ='GIA CONG LAMINATE'!$R$8 -> 46093.448
A27: =IF('GIA CONG LAMINATE'!A82="CT","",'GIA CONG LAMINATE'!A82) -> 0 | B27: =IF('GIA CONG LAMINATE'!A82="CT","",'GIA CONG LAMINATE'!B82) -> 0 | C27: =IF('GIA CONG LAMINATE'!A82="CT","",'GIA CONG LAMINATE'!C82) -> 0 | D27: =IF('GIA CONG LAMINATE'!A82="CT","",'GIA CONG LAMINATE'!D82) -> 0 | E27: =IF('GIA CONG LAMINATE'!A82="CT","",'GIA CONG LAMINATE'!E82) -> 0 | F27: =IF('GIA CONG LAMINATE'!A82="CT","",'GIA CONG LAMINATE'!F82) -> 0 | G27: =IF('GIA CONG LAMINATE'!A82="CT","",'GIA CONG LAMINATE'!L82) -> 0 | H27: =IF('GIA CONG LAMINATE'!A82="CT","",'GIA CONG LAMINATE'!H82) -> 0 | I27: =IF('GIA CONG LAMINATE'!A82="CT","",'GIA CONG LAMINATE'!I82) -> 0 | J27: =IF('GIA CONG LAMINATE'!A82="CT","",'GIA CONG LAMINATE'!J82) -> 0 | K27: =IF('GIA CONG LAMINATE'!A82="CT","",'GIA CONG LAMINATE'!K82) -> 0 | L27: =IF('GIA CONG LAMINATE'!A82="CT","",'GIA CONG LAMINATE'!L82) -> 0 | M27: =IF('GIA CONG LAMINATE'!A82="CT","",'GIA CONG LAMINATE'!M82) -> 0 | N27: =IF('GIA CONG LAMINATE'!A82="CT","",'GIA CONG LAMINATE'!N82) -> 0 | O27: =IF('GIA CONG LAMINATE'!A82="CT","",'GIA CONG LAMINATE'!O82) -> 0 | P27: =IF('GIA CONG LAMINATE'!A82="CT","",'GIA CONG LAMINATE'!R82) -> 0 | Q27: =IF('GIA CONG LAMINATE'!A82="CT","",'GIA CONG LAMINATE'!S82) -> 0 | R27: =IF('GIA CONG LAMINATE'!A82="CT","",'GIA CONG LAMINATE'!$J$7) -> 0 | T27: ='GIA CONG LAMINATE'!$R$6 -> 46091.448 | U27: ='GIA CONG LAMINATE'!$R$7 -> 2 | V27: ='GIA CONG LAMINATE'!$R$8 -> 46093.448
A28: =IF('GIA CONG LAMINATE'!A83="CT","",'GIA CONG LAMINATE'!A83) -> 0 | B28: =IF('GIA CONG LAMINATE'!A83="CT","",'GIA CONG LAMINATE'!B83) -> - Dán cạnh thẳng tích chữ "T", dán cạnh vát 45 độ tích chữ "V" vào ô dán cạnh tương ứng. | C28: =IF('GIA CONG LAMINATE'!A83="CT","",'GIA CONG LAMINATE'!C83) -> 0 | D28: =IF('GIA CONG LAMINATE'!A83="CT","",'GIA CONG LAMINATE'!D83) -> 0 | E28: =IF('GIA CONG LAMINATE'!A83="CT","",'GIA CONG LAMINATE'!E83) -> 0 | F28: =IF('GIA CONG LAMINATE'!A83="CT","",'GIA CONG LAMINATE'!F83) -> 0 | G28: =IF('GIA CONG LAMINATE'!A83="CT","",'GIA CONG LAMINATE'!L83) -> 0 | H28: =IF('GIA CONG LAMINATE'!A83="CT","",'GIA CONG LAMINATE'!H83) -> 0 | I28: =IF('GIA CONG LAMINATE'!A83="CT","",'GIA CONG LAMINATE'!I83) -> 0 | J28: =IF('GIA CONG LAMINATE'!A83="CT","",'GIA CONG LAMINATE'!J83) -> 0 | K28: =IF('GIA CONG LAMINATE'!A83="CT","",'GIA CONG LAMINATE'!K83) -> 0 | L28: =IF('GIA CONG LAMINATE'!A83="CT","",'GIA CONG LAMINATE'!L83) -> 0 | M28: =IF('GIA CONG LAMINATE'!A83="CT","",'GIA CONG LAMINATE'!M83) -> 0 | N28: =IF('GIA CONG LAMINATE'!A83="CT","",'GIA CONG LAMINATE'!N83) -> 0 | O28: =IF('GIA CONG LAMINATE'!A83="CT","",'GIA CONG LAMINATE'!O83) -> 0 | P28: =IF('GIA CONG LAMINATE'!A83="CT","",'GIA CONG LAMINATE'!R83) -> 0 | Q28: =IF('GIA CONG LAMINATE'!A83="CT","",'GIA CONG LAMINATE'!S83) -> 0 | R28: =IF('GIA CONG LAMINATE'!A83="CT","",'GIA CONG LAMINATE'!$J$7) -> 0 | T28: ='GIA CONG LAMINATE'!$R$6 -> 46091.448 | U28: ='GIA CONG LAMINATE'!$R$7 -> 2 | V28: ='GIA CONG LAMINATE'!$R$8 -> 46093.448
A29: =IF('GIA CONG LAMINATE'!A84="CT","",'GIA CONG LAMINATE'!A84) -> 0 | B29: =IF('GIA CONG LAMINATE'!A84="CT","",'GIA CONG LAMINATE'!B84) -> - Chiều vân ván điền vào cột "CAO" ở bảng trên. | C29: =IF('GIA CONG LAMINATE'!A84="CT","",'GIA CONG LAMINATE'!C84) -> 0 | D29: =IF('GIA CONG LAMINATE'!A84="CT","",'GIA CONG LAMINATE'!D84) -> 0 | E29: =IF('GIA CONG LAMINATE'!A84="CT","",'GIA CONG LAMINATE'!E84) -> 0 | F29: =IF('GIA CONG LAMINATE'!A84="CT","",'GIA CONG LAMINATE'!F84) -> 0 | G29: =IF('GIA CONG LAMINATE'!A84="CT","",'GIA CONG LAMINATE'!L84) -> 0 | H29: =IF('GIA CONG LAMINATE'!A84="CT","",'GIA CONG LAMINATE'!H84) -> 0 | I29: =IF('GIA CONG LAMINATE'!A84="CT","",'GIA CONG LAMINATE'!I84) -> 0 | J29: =IF('GIA CONG LAMINATE'!A84="CT","",'GIA CONG LAMINATE'!J84) -> 0 | K29: =IF('GIA CONG LAMINATE'!A84="CT","",'GIA CONG LAMINATE'!K84) -> 0 | L29: =IF('GIA CONG LAMINATE'!A84="CT","",'GIA CONG LAMINATE'!L84) -> 0 | M29: =IF('GIA CONG LAMINATE'!A84="CT","",'GIA CONG LAMINATE'!M84) -> 0 | N29: =IF('GIA CONG LAMINATE'!A84="CT","",'GIA CONG LAMINATE'!N84) -> 0 | O29: =IF('GIA CONG LAMINATE'!A84="CT","",'GIA CONG LAMINATE'!O84) -> 0 | P29: =IF('GIA CONG LAMINATE'!A84="CT","",'GIA CONG LAMINATE'!R84) -> 0 | Q29: =IF('GIA CONG LAMINATE'!A84="CT","",'GIA CONG LAMINATE'!S84) -> 0 | R29: =IF('GIA CONG LAMINATE'!A84="CT","",'GIA CONG LAMINATE'!$J$7) -> 0 | T29: ='GIA CONG LAMINATE'!$R$6 -> 46091.448 | U29: ='GIA CONG LAMINATE'!$R$7 -> 2 | V29: ='GIA CONG LAMINATE'!$R$8 -> 46093.448
A30: =IF('GIA CONG LAMINATE'!A85="CT","",'GIA CONG LAMINATE'!A85) -> 0 | B30: =IF('GIA CONG LAMINATE'!A85="CT","",'GIA CONG LAMINATE'!B85) -> 0 | C30: =IF('GIA CONG LAMINATE'!A85="CT","",'GIA CONG LAMINATE'!C85) -> 0 | D30: =IF('GIA CONG LAMINATE'!A85="CT","",'GIA CONG LAMINATE'!D85) -> 0 | E30: =IF('GIA CONG LAMINATE'!A85="CT","",'GIA CONG LAMINATE'!E85) -> 0 | F30: =IF('GIA CONG LAMINATE'!A85="CT","",'GIA CONG LAMINATE'!F85) -> 0 | G30: =IF('GIA CONG LAMINATE'!A85="CT","",'GIA CONG LAMINATE'!L85) -> 0 | H30: =IF('GIA CONG LAMINATE'!A85="CT","",'GIA CONG LAMINATE'!H85) -> 0 | I30: =IF('GIA CONG LAMINATE'!A85="CT","",'GIA CONG LAMINATE'!I85) -> 0 | J30: =IF('GIA CONG LAMINATE'!A85="CT","",'GIA CONG LAMINATE'!J85) -> 0 | K30: =IF('GIA CONG LAMINATE'!A85="CT","",'GIA CONG LAMINATE'!K85) -> 0 | L30: =IF('GIA CONG LAMINATE'!A85="CT","",'GIA CONG LAMINATE'!L85) -> 0 | M30: =IF('GIA CONG LAMINATE'!A85="CT","",'GIA CONG LAMINATE'!M85) -> 0 | N30: =IF('GIA CONG LAMINATE'!A85="CT","",'GIA CONG LAMINATE'!N85) -> 0 | O30: =IF('GIA CONG LAMINATE'!A85="CT","",'GIA CONG LAMINATE'!O85) -> 0 | P30: =IF('GIA CONG LAMINATE'!A85="CT","",'GIA CONG LAMINATE'!R85) -> 0 | Q30: =IF('GIA CONG LAMINATE'!A85="CT","",'GIA CONG LAMINATE'!S85) -> 0 | R30: =IF('GIA CONG LAMINATE'!A85="CT","",'GIA CONG LAMINATE'!$J$7) -> 0 | T30: ='GIA CONG LAMINATE'!$R$6 -> 46091.448 | U30: ='GIA CONG LAMINATE'!$R$7 -> 2 | V30: ='GIA CONG LAMINATE'!$R$8 -> 46093.448
A31: =IF('GIA CONG LAMINATE'!A86="CT","",'GIA CONG LAMINATE'!A86) -> 0 | B31: =IF('GIA CONG LAMINATE'!A86="CT","",'GIA CONG LAMINATE'!B86) -> 0 | C31: =IF('GIA CONG LAMINATE'!A86="CT","",'GIA CONG LAMINATE'!C86) -> 0 | D31: =IF('GIA CONG LAMINATE'!A86="CT","",'GIA CONG LAMINATE'!D86) -> 0 | E31: =IF('GIA CONG LAMINATE'!A86="CT","",'GIA CONG LAMINATE'!E86) -> 0 | F31: =IF('GIA CONG LAMINATE'!A86="CT","",'GIA CONG LAMINATE'!F86) -> 0 | G31: =IF('GIA CONG LAMINATE'!A86="CT","",'GIA CONG LAMINATE'!L86) -> 0 | H31: =IF('GIA CONG LAMINATE'!A86="CT","",'GIA CONG LAMINATE'!H86) -> 0 | I31: =IF('GIA CONG LAMINATE'!A86="CT","",'GIA CONG LAMINATE'!I86) -> 0 | J31: =IF('GIA CONG LAMINATE'!A86="CT","",'GIA CONG LAMINATE'!J86) -> 0 | K31: =IF('GIA CONG LAMINATE'!A86="CT","",'GIA CONG LAMINATE'!K86) -> 0 | L31: =IF('GIA CONG LAMINATE'!A86="CT","",'GIA CONG LAMINATE'!L86) -> 0 | M31: =IF('GIA CONG LAMINATE'!A86="CT","",'GIA CONG LAMINATE'!M86) -> 0 | N31: =IF('GIA CONG LAMINATE'!A86="CT","",'GIA CONG LAMINATE'!N86) -> 0 | O31: =IF('GIA CONG LAMINATE'!A86="CT","",'GIA CONG LAMINATE'!O86) -> 0 | P31: =IF('GIA CONG LAMINATE'!A86="CT","",'GIA CONG LAMINATE'!R86) -> 0 | Q31: =IF('GIA CONG LAMINATE'!A86="CT","",'GIA CONG LAMINATE'!S86) -> 0 | R31: =IF('GIA CONG LAMINATE'!A86="CT","",'GIA CONG LAMINATE'!$J$7) -> 0 | T31: ='GIA CONG LAMINATE'!$R$6 -> 46091.448 | U31: ='GIA CONG LAMINATE'!$R$7 -> 2 | V31: ='GIA CONG LAMINATE'!$R$8 -> 46093.448
A32: =IF('GIA CONG LAMINATE'!A87="CT","",'GIA CONG LAMINATE'!A87) -> 0 | B32: =IF('GIA CONG LAMINATE'!A87="CT","",'GIA CONG LAMINATE'!B87) -> 0 | C32: =IF('GIA CONG LAMINATE'!A87="CT","",'GIA CONG LAMINATE'!C87) -> 0 | D32: =IF('GIA CONG LAMINATE'!A87="CT","",'GIA CONG LAMINATE'!D87) -> XÁC NHẬN BÊN MUA HÀNG | E32: =IF('GIA CONG LAMINATE'!A87="CT","",'GIA CONG LAMINATE'!E87) -> 0 | F32: =IF('GIA CONG LAMINATE'!A87="CT","",'GIA CONG LAMINATE'!F87) -> 0 | G32: =IF('GIA CONG LAMINATE'!A87="CT","",'GIA CONG LAMINATE'!L87) -> KẾ TOÁN XÁC NHẬN | H32: =IF('GIA CONG LAMINATE'!A87="CT","",'GIA CONG LAMINATE'!H87) -> 0 | I32: =IF('GIA CONG LAMINATE'!A87="CT","",'GIA CONG LAMINATE'!I87) -> 0 | J32: =IF('GIA CONG LAMINATE'!A87="CT","",'GIA CONG LAMINATE'!J87) -> 0 | K32: =IF('GIA CONG LAMINATE'!A87="CT","",'GIA CONG LAMINATE'!K87) -> 0 | L32: =IF('GIA CONG LAMINATE'!A87="CT","",'GIA CONG LAMINATE'!L87) -> KẾ TOÁN XÁC NHẬN | M32: =IF('GIA CONG LAMINATE'!A87="CT","",'GIA CONG LAMINATE'!M87) -> 0 | N32: =IF('GIA CONG LAMINATE'!A87="CT","",'GIA CONG LAMINATE'!N87) -> 0 | O32: =IF('GIA CONG LAMINATE'!A87="CT","",'GIA CONG LAMINATE'!O87) -> 0 | P32: =IF('GIA CONG LAMINATE'!A87="CT","",'GIA CONG LAMINATE'!R87) -> 0 | Q32: =IF('GIA CONG LAMINATE'!A87="CT","",'GIA CONG LAMINATE'!S87) -> 0 | R32: =IF('GIA CONG LAMINATE'!A87="CT","",'GIA CONG LAMINATE'!$J$7) -> 0 | T32: ='GIA CONG LAMINATE'!$R$6 -> 46091.448 | U32: ='GIA CONG LAMINATE'!$R$7 -> 2 | V32: ='GIA CONG LAMINATE'!$R$8 -> 46093.448
A33: =IF('GIA CONG LAMINATE'!A86="CT","",'GIA CONG LAMINATE'!A86) -> 0 | B33: =IF('GIA CONG LAMINATE'!A86="CT","",'GIA CONG LAMINATE'!B86) -> 0 | C33: =IF('GIA CONG LAMINATE'!A86="CT","",'GIA CONG LAMINATE'!C86) -> 0 | D33: =IF('GIA CONG LAMINATE'!A86="CT","",'GIA CONG LAMINATE'!D86) -> 0 | E33: =IF('GIA CONG LAMINATE'!A86="CT","",'GIA CONG LAMINATE'!E86) -> 0 | F33: =IF('GIA CONG LAMINATE'!A86="CT","",'GIA CONG LAMINATE'!F86) -> 0 | G33: =IF('GIA CONG LAMINATE'!A86="CT","",'GIA CONG LAMINATE'!L86) -> 0 | H33: =IF('GIA CONG LAMINATE'!A86="CT","",'GIA CONG LAMINATE'!H86) -> 0 | I33: =IF('GIA CONG LAMINATE'!A86="CT","",'GIA CONG LAMINATE'!I86) -> 0 | J33: =IF('GIA CONG LAMINATE'!A86="CT","",'GIA CONG LAMINATE'!J86) -> 0 | K33: =IF('GIA CONG LAMINATE'!A86="CT","",'GIA CONG LAMINATE'!K86) -> 0 | L33: =IF('GIA CONG LAMINATE'!A86="CT","",'GIA CONG LAMINATE'!L86) -> 0 | M33: =IF('GIA CONG LAMINATE'!A86="CT","",'GIA CONG LAMINATE'!M86) -> 0 | N33: =IF('GIA CONG LAMINATE'!A86="CT","",'GIA CONG LAMINATE'!N86) -> 0 | O33: =IF('GIA CONG LAMINATE'!A86="CT","",'GIA CONG LAMINATE'!O86) -> 0 | P33: =IF('GIA CONG LAMINATE'!A86="CT","",'GIA CONG LAMINATE'!R86) -> 0 | Q33: =IF('GIA CONG LAMINATE'!A86="CT","",'GIA CONG LAMINATE'!S86) -> 0 | R33: =IF('GIA CONG LAMINATE'!A86="CT","",'GIA CONG LAMINATE'!$J$7) -> 0 | T33: ='GIA CONG LAMINATE'!$R$6 -> 46091.448 | U33: ='GIA CONG LAMINATE'!$R$7 -> 2 | V33: ='GIA CONG LAMINATE'!$R$8 -> 46093.448
A34: =IF('GIA CONG LAMINATE'!A87="CT","",'GIA CONG LAMINATE'!A87) -> 0 | B34: =IF('GIA CONG LAMINATE'!A87="CT","",'GIA CONG LAMINATE'!B87) -> 0 | C34: =IF('GIA CONG LAMINATE'!A87="CT","",'GIA CONG LAMINATE'!C87) -> 0 | D34: =IF('GIA CONG LAMINATE'!A87="CT","",'GIA CONG LAMINATE'!D87) -> XÁC NHẬN BÊN MUA HÀNG | E34: =IF('GIA CONG LAMINATE'!A87="CT","",'GIA CONG LAMINATE'!E87) -> 0 | F34: =IF('GIA CONG LAMINATE'!A87="CT","",'GIA CONG LAMINATE'!F87) -> 0 | G34: =IF('GIA CONG LAMINATE'!A87="CT","",'GIA CONG LAMINATE'!L87) -> KẾ TOÁN XÁC NHẬN | H34: =IF('GIA CONG LAMINATE'!A87="CT","",'GIA CONG LAMINATE'!H87) -> 0 | I34: =IF('GIA CONG LAMINATE'!A87="CT","",'GIA CONG LAMINATE'!I87) -> 0 | J34: =IF('GIA CONG LAMINATE'!A87="CT","",'GIA CONG LAMINATE'!J87) -> 0 | K34: =IF('GIA CONG LAMINATE'!A87="CT","",'GIA CONG LAMINATE'!K87) -> 0 | L34: =IF('GIA CONG LAMINATE'!A87="CT","",'GIA CONG LAMINATE'!L87) -> KẾ TOÁN XÁC NHẬN | M34: =IF('GIA CONG LAMINATE'!A87="CT","",'GIA CONG LAMINATE'!M87) -> 0 | N34: =IF('GIA CONG LAMINATE'!A87="CT","",'GIA CONG LAMINATE'!N87) -> 0 | O34: =IF('GIA CONG LAMINATE'!A87="CT","",'GIA CONG LAMINATE'!O87) -> 0 | P34: =IF('GIA CONG LAMINATE'!A87="CT","",'GIA CONG LAMINATE'!R87) -> 0 | Q34: =IF('GIA CONG LAMINATE'!A87="CT","",'GIA CONG LAMINATE'!S87) -> 0 | R34: =IF('GIA CONG LAMINATE'!A87="CT","",'GIA CONG LAMINATE'!$J$7) -> 0 | T34: ='GIA CONG LAMINATE'!$R$6 -> 46091.448 | U34: ='GIA CONG LAMINATE'!$R$7 -> 2 | V34: ='GIA CONG LAMINATE'!$R$8 -> 46093.448
A35: =IF('GIA CONG LAMINATE'!A88="CT","",'GIA CONG LAMINATE'!A88) -> 0 | B35: =IF('GIA CONG LAMINATE'!A88="CT","",'GIA CONG LAMINATE'!B88) -> 0 | C35: =IF('GIA CONG LAMINATE'!A88="CT","",'GIA CONG LAMINATE'!C88) -> 0 | D35: =IF('GIA CONG LAMINATE'!A88="CT","",'GIA CONG LAMINATE'!D88) -> (Ký, ghi rõ họ tên) | E35: =IF('GIA CONG LAMINATE'!A88="CT","",'GIA CONG LAMINATE'!E88) -> 0 | F35: =IF('GIA CONG LAMINATE'!A88="CT","",'GIA CONG LAMINATE'!F88) -> 0 | G35: =IF('GIA CONG LAMINATE'!A88="CT","",'GIA CONG LAMINATE'!L88) -> (Ký, ghi rõ họ tên) | H35: =IF('GIA CONG LAMINATE'!A88="CT","",'GIA CONG LAMINATE'!H88) -> 0 | I35: =IF('GIA CONG LAMINATE'!A88="CT","",'GIA CONG LAMINATE'!I88) -> 0 | J35: =IF('GIA CONG LAMINATE'!A88="CT","",'GIA CONG LAMINATE'!J88) -> 0 | K35: =IF('GIA CONG LAMINATE'!A88="CT","",'GIA CONG LAMINATE'!K88) -> 0 | L35: =IF('GIA CONG LAMINATE'!A88="CT","",'GIA CONG LAMINATE'!L88) -> (Ký, ghi rõ họ tên) | M35: =IF('GIA CONG LAMINATE'!A88="CT","",'GIA CONG LAMINATE'!M88) -> 0 | N35: =IF('GIA CONG LAMINATE'!A88="CT","",'GIA CONG LAMINATE'!N88) -> 0 | O35: =IF('GIA CONG LAMINATE'!A88="CT","",'GIA CONG LAMINATE'!O88) -> 0 | P35: =IF('GIA CONG LAMINATE'!A88="CT","",'GIA CONG LAMINATE'!R88) -> 0 | Q35: =IF('GIA CONG LAMINATE'!A88="CT","",'GIA CONG LAMINATE'!S88) -> 0 | R35: =IF('GIA CONG LAMINATE'!A88="CT","",'GIA CONG LAMINATE'!$J$7) -> 0 | T35: ='GIA CONG LAMINATE'!$R$6 -> 46091.448 | U35: ='GIA CONG LAMINATE'!$R$7 -> 2 | V35: ='GIA CONG LAMINATE'!$R$8 -> 46093.448
A36: =IF('GIA CONG LAMINATE'!A89="CT","",'GIA CONG LAMINATE'!A89) -> 0 | B36: =IF('GIA CONG LAMINATE'!A89="CT","",'GIA CONG LAMINATE'!B89) -> 0 | C36: =IF('GIA CONG LAMINATE'!A89="CT","",'GIA CONG LAMINATE'!C89) -> 0 | D36: =IF('GIA CONG LAMINATE'!A89="CT","",'GIA CONG LAMINATE'!D89) -> 0 | E36: =IF('GIA CONG LAMINATE'!A89="CT","",'GIA CONG LAMINATE'!E89) -> 0 | F36: =IF('GIA CONG LAMINATE'!A89="CT","",'GIA CONG LAMINATE'!F89) -> 0 | G36: =IF('GIA CONG LAMINATE'!A89="CT","",'GIA CONG LAMINATE'!L89) -> 0 | H36: =IF('GIA CONG LAMINATE'!A89="CT","",'GIA CONG LAMINATE'!H89) -> 0 | I36: =IF('GIA CONG LAMINATE'!A89="CT","",'GIA CONG LAMINATE'!I89) -> 0 | J36: =IF('GIA CONG LAMINATE'!A89="CT","",'GIA CONG LAMINATE'!J89) -> 0 | K36: =IF('GIA CONG LAMINATE'!A89="CT","",'GIA CONG LAMINATE'!K89) -> 0 | L36: =IF('GIA CONG LAMINATE'!A89="CT","",'GIA CONG LAMINATE'!L89) -> 0 | M36: =IF('GIA CONG LAMINATE'!A89="CT","",'GIA CONG LAMINATE'!M89) -> 0 | N36: =IF('GIA CONG LAMINATE'!A89="CT","",'GIA CONG LAMINATE'!N89) -> 0 | O36: =IF('GIA CONG LAMINATE'!A89="CT","",'GIA CONG LAMINATE'!O89) -> 0 | P36: =IF('GIA CONG LAMINATE'!A89="CT","",'GIA CONG LAMINATE'!R89) -> 0 | Q36: =IF('GIA CONG LAMINATE'!A89="CT","",'GIA CONG LAMINATE'!S89) -> 0 | R36: =IF('GIA CONG LAMINATE'!A89="CT","",'GIA CONG LAMINATE'!$J$7) -> 0 | T36: ='GIA CONG LAMINATE'!$R$6 -> 46091.448 | U36: ='GIA CONG LAMINATE'!$R$7 -> 2 | V36: ='GIA CONG LAMINATE'!$R$8 -> 46093.448
A37: =IF('GIA CONG LAMINATE'!A90="CT","",'GIA CONG LAMINATE'!A90) -> 0 | B37: =IF('GIA CONG LAMINATE'!A90="CT","",'GIA CONG LAMINATE'!B90) -> 0 | C37: =IF('GIA CONG LAMINATE'!A90="CT","",'GIA CONG LAMINATE'!C90) -> 0 | D37: =IF('GIA CONG LAMINATE'!A90="CT","",'GIA CONG LAMINATE'!D90) -> 0 | E37: =IF('GIA CONG LAMINATE'!A90="CT","",'GIA CONG LAMINATE'!E90) -> 0 | F37: =IF('GIA CONG LAMINATE'!A90="CT","",'GIA CONG LAMINATE'!F90) -> 0 | G37: =IF('GIA CONG LAMINATE'!A90="CT","",'GIA CONG LAMINATE'!L90) -> 0 | H37: =IF('GIA CONG LAMINATE'!A90="CT","",'GIA CONG LAMINATE'!H90) -> 0 | I37: =IF('GIA CONG LAMINATE'!A90="CT","",'GIA CONG LAMINATE'!I90) -> 0 | J37: =IF('GIA CONG LAMINATE'!A90="CT","",'GIA CONG LAMINATE'!J90) -> 0 | K37: =IF('GIA CONG LAMINATE'!A90="CT","",'GIA CONG LAMINATE'!K90) -> 0 | L37: =IF('GIA CONG LAMINATE'!A90="CT","",'GIA CONG LAMINATE'!L90) -> 0 | M37: =IF('GIA CONG LAMINATE'!A90="CT","",'GIA CONG LAMINATE'!M90) -> 0 | N37: =IF('GIA CONG LAMINATE'!A90="CT","",'GIA CONG LAMINATE'!N90) -> 0 | O37: =IF('GIA CONG LAMINATE'!A90="CT","",'GIA CONG LAMINATE'!O90) -> 0 | P37: =IF('GIA CONG LAMINATE'!A90="CT","",'GIA CONG LAMINATE'!R90) -> 0 | Q37: =IF('GIA CONG LAMINATE'!A90="CT","",'GIA CONG LAMINATE'!S90) -> 0 | R37: =IF('GIA CONG LAMINATE'!A90="CT","",'GIA CONG LAMINATE'!$J$7) -> 0 | T37: ='GIA CONG LAMINATE'!$R$6 -> 46091.448 | U37: ='GIA CONG LAMINATE'!$R$7 -> 2 | V37: ='GIA CONG LAMINATE'!$R$8 -> 46093.448
A38: =IF('GIA CONG LAMINATE'!A91="CT","",'GIA CONG LAMINATE'!A91) -> 0 | B38: =IF('GIA CONG LAMINATE'!A91="CT","",'GIA CONG LAMINATE'!B91) -> 1 | C38: =IF('GIA CONG LAMINATE'!A91="CT","",'GIA CONG LAMINATE'!C91) -> 0 | D38: =IF('GIA CONG LAMINATE'!A91="CT","",'GIA CONG LAMINATE'!D91) -> Đơn giá trên chưa bao gồm VAT.Đúng sai ±1 mm. | E38: =IF('GIA CONG LAMINATE'!A91="CT","",'GIA CONG LAMINATE'!E91) -> 0 | F38: =IF('GIA CONG LAMINATE'!A91="CT","",'GIA CONG LAMINATE'!F91) -> 0 | G38: =IF('GIA CONG LAMINATE'!A91="CT","",'GIA CONG LAMINATE'!L91) -> 0 | H38: =IF('GIA CONG LAMINATE'!A91="CT","",'GIA CONG LAMINATE'!H91) -> 0 | I38: =IF('GIA CONG LAMINATE'!A91="CT","",'GIA CONG LAMINATE'!I91) -> 0 | J38: =IF('GIA CONG LAMINATE'!A91="CT","",'GIA CONG LAMINATE'!J91) -> 0 | K38: =IF('GIA CONG LAMINATE'!A91="CT","",'GIA CONG LAMINATE'!K91) -> 0 | L38: =IF('GIA CONG LAMINATE'!A91="CT","",'GIA CONG LAMINATE'!L91) -> 0 | M38: =IF('GIA CONG LAMINATE'!A91="CT","",'GIA CONG LAMINATE'!M91) -> 0 | N38: =IF('GIA CONG LAMINATE'!A91="CT","",'GIA CONG LAMINATE'!N91) -> 0 | O38: =IF('GIA CONG LAMINATE'!A91="CT","",'GIA CONG LAMINATE'!O91) -> 0 | P38: =IF('GIA CONG LAMINATE'!A91="CT","",'GIA CONG LAMINATE'!R91) -> 0 | Q38: =IF('GIA CONG LAMINATE'!A91="CT","",'GIA CONG LAMINATE'!S91) -> 0 | R38: =IF('GIA CONG LAMINATE'!A91="CT","",'GIA CONG LAMINATE'!$J$7) -> 0 | T38: ='GIA CONG LAMINATE'!$R$6 -> 46091.448 | U38: ='GIA CONG LAMINATE'!$R$7 -> 2 | V38: ='GIA CONG LAMINATE'!$R$8 -> 46093.448
